[2019-02-25 11:11:29,693][Thread-1:130944][task_id:django.request][log.py:228][ERROR][Internal Server Error: /]
Traceback (most recent call last):
  File "D:\Project\Website\venv\lib\site-packages\django\core\handlers\exception.py", line 34, in inner
    response = get_response(request)
  File "D:\Project\Website\venv\lib\site-packages\django\core\handlers\base.py", line 126, in _get_response
    response = self.process_exception_by_middleware(e, request)
  File "D:\Project\Website\venv\lib\site-packages\django\core\handlers\base.py", line 124, in _get_response
    response = wrapped_callback(request, *callback_args, **callback_kwargs)
TypeError: showMainPage() missing 1 required positional argument: 'path'
[2019-02-25 11:12:44,263][Thread-1:132356][task_id:root][views.py:14][INFO][Accessing Page / with showMainPage]
[2019-02-25 11:12:44,273][Thread-1:132356][task_id:django.request][log.py:228][WARNING][Not Found: /s/index.html]
[2019-02-25 11:12:44,338][Thread-1:132356][task_id:django.request][log.py:228][WARNING][Not Found: /favicon.ico]
[2019-02-25 11:13:29,330][Thread-1:59624][task_id:django.request][log.py:228][WARNING][Not Found: /s/index.html]
[2019-02-25 11:13:52,672][Thread-1:127092][task_id:staticApp.views][views.py:14][INFO][Accessing Page index.html with showMainPage]
[2019-02-25 11:13:52,700][Thread-1:127092][task_id:django.request][log.py:228][WARNING][Not Found: /assets/css/main.css]
[2019-02-25 11:13:52,716][Thread-3:126120][task_id:django.request][log.py:228][WARNING][Not Found: /assets/css/prism.css]
[2019-02-25 11:13:52,720][Thread-1:127092][task_id:django.request][log.py:228][WARNING][Not Found: /images/cf915d_1.jpg]
[2019-02-25 11:13:52,739][Thread-1:127092][task_id:django.request][log.py:228][WARNING][Not Found: /assets/js/getpv.js]
[2019-02-25 11:13:52,747][Thread-3:126120][task_id:django.request][log.py:228][WARNING][Not Found: /assets/js/skel.min.js]
[2019-02-25 11:13:52,754][Thread-4:131204][task_id:django.request][log.py:228][WARNING][Not Found: /assets/js/util.js]
[2019-02-25 11:13:52,761][Thread-5:123780][task_id:django.request][log.py:228][WARNING][Not Found: /assets/js/main.js]
[2019-02-25 11:13:52,767][Thread-1:127092][task_id:django.request][log.py:228][WARNING][Not Found: /images/friend_01.jpg]
[2019-02-25 11:13:52,773][Thread-3:126120][task_id:django.request][log.py:228][WARNING][Not Found: /assets/js/prism.js]
[2019-02-25 11:13:52,786][Thread-4:131204][task_id:django.request][log.py:228][WARNING][Not Found: /images/friend_02.jpg]
[2019-02-25 11:13:52,789][Thread-5:123780][task_id:django.request][log.py:228][WARNING][Not Found: /images/pic09.jpg]
[2019-02-25 11:13:53,938][Thread-5:123780][task_id:django.request][log.py:228][WARNING][Not Found: /assets/js/getpv.js]
[2019-02-25 11:13:54,086][Thread-5:123780][task_id:django.request][log.py:228][WARNING][Not Found: /assets/js/skel.min.js]
[2019-02-25 11:13:54,106][Thread-5:123780][task_id:django.request][log.py:228][WARNING][Not Found: /assets/js/util.js]
[2019-02-25 11:13:54,123][Thread-5:123780][task_id:django.request][log.py:228][WARNING][Not Found: /assets/js/main.js]
[2019-02-25 11:13:54,142][Thread-5:123780][task_id:django.request][log.py:228][WARNING][Not Found: /assets/js/prism.js]
[2019-02-25 11:13:59,680][Thread-5:123780][task_id:django.request][log.py:228][WARNING][Not Found: /assets/css/main.css]
[2019-02-25 11:13:59,690][Thread-4:131204][task_id:django.request][log.py:228][WARNING][Not Found: /assets/css/prism.css]
[2019-02-25 11:20:38,800][Thread-1:133888][task_id:root][views.py:14][INFO][Accessing Page / with showMainPage]
[2019-02-25 11:20:38,855][Thread-1:133888][task_id:staticApp.views][views.py:14][INFO][Accessing Page index.html with showMainPage]
[2019-02-25 11:20:39,161][Thread-3:133920][task_id:django.request][log.py:228][ERROR][Internal Server Error: /assets/css/prism.css]
Traceback (most recent call last):
  File "D:\Project\Website\venv\lib\site-packages\django\core\handlers\exception.py", line 34, in inner
    response = get_response(request)
  File "D:\Project\Website\venv\lib\site-packages\django\core\handlers\base.py", line 126, in _get_response
    response = self.process_exception_by_middleware(e, request)
  File "D:\Project\Website\venv\lib\site-packages\django\core\handlers\base.py", line 124, in _get_response
    response = wrapped_callback(request, *callback_args, **callback_kwargs)
  File "D:\Project\Website\staticApp\views.py", line 21, in showAssets
    with open('./assets/' + path, encoding='UTF-8') as f:
FileNotFoundError: [Errno 2] No such file or directory: './assets/css/prism.css'
[2019-02-25 11:20:39,219][Thread-1:133888][task_id:django.request][log.py:228][ERROR][Internal Server Error: /assets/css/main.css]
Traceback (most recent call last):
  File "D:\Project\Website\venv\lib\site-packages\django\core\handlers\exception.py", line 34, in inner
    response = get_response(request)
  File "D:\Project\Website\venv\lib\site-packages\django\core\handlers\base.py", line 126, in _get_response
    response = self.process_exception_by_middleware(e, request)
  File "D:\Project\Website\venv\lib\site-packages\django\core\handlers\base.py", line 124, in _get_response
    response = wrapped_callback(request, *callback_args, **callback_kwargs)
  File "D:\Project\Website\staticApp\views.py", line 21, in showAssets
    with open('./assets/' + path, encoding='UTF-8') as f:
FileNotFoundError: [Errno 2] No such file or directory: './assets/css/main.css'
[2019-02-25 11:20:39,454][Thread-5:133936][task_id:django.request][log.py:228][ERROR][Internal Server Error: /assets/js/getpv.js]
Traceback (most recent call last):
  File "D:\Project\Website\venv\lib\site-packages\django\core\handlers\exception.py", line 34, in inner
    response = get_response(request)
  File "D:\Project\Website\venv\lib\site-packages\django\core\handlers\base.py", line 126, in _get_response
    response = self.process_exception_by_middleware(e, request)
  File "D:\Project\Website\venv\lib\site-packages\django\core\handlers\base.py", line 124, in _get_response
    response = wrapped_callback(request, *callback_args, **callback_kwargs)
  File "D:\Project\Website\staticApp\views.py", line 26, in showAssets
    with open('./assets/' + path, encoding='UTF-8') as f:
FileNotFoundError: [Errno 2] No such file or directory: './static/js/getpv.js'
[2019-02-25 11:20:39,524][Thread-4:133924][task_id:django.request][log.py:228][ERROR][Internal Server Error: /images/cf915d_1.jpg]
Traceback (most recent call last):
  File "D:\Project\Website\venv\lib\site-packages\django\core\handlers\exception.py", line 34, in inner
    response = get_response(request)
  File "D:\Project\Website\venv\lib\site-packages\django\core\handlers\base.py", line 126, in _get_response
    response = self.process_exception_by_middleware(e, request)
  File "D:\Project\Website\venv\lib\site-packages\django\core\handlers\base.py", line 124, in _get_response
    response = wrapped_callback(request, *callback_args, **callback_kwargs)
  File "D:\Project\Website\staticApp\views.py", line 35, in showImages
    with open('./images/'+path, mode="rb") as f:
FileNotFoundError: [Errno 2] No such file or directory: './static/cf915d_1.jpg'
[2019-02-25 11:20:39,591][Thread-7:133944][task_id:django.request][log.py:228][ERROR][Internal Server Error: /assets/js/util.js]
Traceback (most recent call last):
  File "D:\Project\Website\venv\lib\site-packages\django\core\handlers\exception.py", line 34, in inner
    response = get_response(request)
  File "D:\Project\Website\venv\lib\site-packages\django\core\handlers\base.py", line 126, in _get_response
    response = self.process_exception_by_middleware(e, request)
  File "D:\Project\Website\venv\lib\site-packages\django\core\handlers\base.py", line 124, in _get_response
    response = wrapped_callback(request, *callback_args, **callback_kwargs)
  File "D:\Project\Website\staticApp\views.py", line 26, in showAssets
    with open('./assets/' + path, encoding='UTF-8') as f:
FileNotFoundError: [Errno 2] No such file or directory: './static/js/util.js'
[2019-02-25 11:20:39,594][Thread-6:133940][task_id:django.request][log.py:228][ERROR][Internal Server Error: /assets/js/skel.min.js]
Traceback (most recent call last):
  File "D:\Project\Website\venv\lib\site-packages\django\core\handlers\exception.py", line 34, in inner
    response = get_response(request)
  File "D:\Project\Website\venv\lib\site-packages\django\core\handlers\base.py", line 126, in _get_response
    response = self.process_exception_by_middleware(e, request)
  File "D:\Project\Website\venv\lib\site-packages\django\core\handlers\base.py", line 124, in _get_response
    response = wrapped_callback(request, *callback_args, **callback_kwargs)
  File "D:\Project\Website\staticApp\views.py", line 26, in showAssets
    with open('./assets/' + path, encoding='UTF-8') as f:
FileNotFoundError: [Errno 2] No such file or directory: './static/js/skel.min.js'
[2019-02-25 11:20:39,952][Thread-1:133888][task_id:django.request][log.py:228][ERROR][Internal Server Error: /assets/js/prism.js]
Traceback (most recent call last):
  File "D:\Project\Website\venv\lib\site-packages\django\core\handlers\exception.py", line 34, in inner
    response = get_response(request)
  File "D:\Project\Website\venv\lib\site-packages\django\core\handlers\base.py", line 126, in _get_response
    response = self.process_exception_by_middleware(e, request)
  File "D:\Project\Website\venv\lib\site-packages\django\core\handlers\base.py", line 124, in _get_response
    response = wrapped_callback(request, *callback_args, **callback_kwargs)
  File "D:\Project\Website\staticApp\views.py", line 26, in showAssets
    with open('./assets/' + path, encoding='UTF-8') as f:
FileNotFoundError: [Errno 2] No such file or directory: './static/js/prism.js'
[2019-02-25 11:20:40,001][Thread-5:133936][task_id:django.request][log.py:228][ERROR][Internal Server Error: /images/friend_01.jpg]
Traceback (most recent call last):
  File "D:\Project\Website\venv\lib\site-packages\django\core\handlers\exception.py", line 34, in inner
    response = get_response(request)
  File "D:\Project\Website\venv\lib\site-packages\django\core\handlers\base.py", line 126, in _get_response
    response = self.process_exception_by_middleware(e, request)
  File "D:\Project\Website\venv\lib\site-packages\django\core\handlers\base.py", line 124, in _get_response
    response = wrapped_callback(request, *callback_args, **callback_kwargs)
  File "D:\Project\Website\staticApp\views.py", line 35, in showImages
    with open('./images/'+path, mode="rb") as f:
FileNotFoundError: [Errno 2] No such file or directory: './static/friend_01.jpg'
[2019-02-25 11:20:40,012][Thread-8:134012][task_id:django.request][log.py:228][ERROR][Internal Server Error: /assets/js/main.js]
Traceback (most recent call last):
  File "D:\Project\Website\venv\lib\site-packages\django\core\handlers\exception.py", line 34, in inner
    response = get_response(request)
  File "D:\Project\Website\venv\lib\site-packages\django\core\handlers\base.py", line 126, in _get_response
    response = self.process_exception_by_middleware(e, request)
  File "D:\Project\Website\venv\lib\site-packages\django\core\handlers\base.py", line 124, in _get_response
    response = wrapped_callback(request, *callback_args, **callback_kwargs)
  File "D:\Project\Website\staticApp\views.py", line 26, in showAssets
    with open('./assets/' + path, encoding='UTF-8') as f:
FileNotFoundError: [Errno 2] No such file or directory: './static/js/main.js'
[2019-02-25 11:20:40,085][Thread-7:133944][task_id:django.request][log.py:228][ERROR][Internal Server Error: /images/pic09.jpg]
Traceback (most recent call last):
  File "D:\Project\Website\venv\lib\site-packages\django\core\handlers\exception.py", line 34, in inner
    response = get_response(request)
  File "D:\Project\Website\venv\lib\site-packages\django\core\handlers\base.py", line 126, in _get_response
    response = self.process_exception_by_middleware(e, request)
  File "D:\Project\Website\venv\lib\site-packages\django\core\handlers\base.py", line 124, in _get_response
    response = wrapped_callback(request, *callback_args, **callback_kwargs)
  File "D:\Project\Website\staticApp\views.py", line 35, in showImages
    with open('./images/'+path, mode="rb") as f:
FileNotFoundError: [Errno 2] No such file or directory: './static/pic09.jpg'
[2019-02-25 11:20:40,112][Thread-4:133924][task_id:django.request][log.py:228][ERROR][Internal Server Error: /images/friend_02.jpg]
Traceback (most recent call last):
  File "D:\Project\Website\venv\lib\site-packages\django\core\handlers\exception.py", line 34, in inner
    response = get_response(request)
  File "D:\Project\Website\venv\lib\site-packages\django\core\handlers\base.py", line 126, in _get_response
    response = self.process_exception_by_middleware(e, request)
  File "D:\Project\Website\venv\lib\site-packages\django\core\handlers\base.py", line 124, in _get_response
    response = wrapped_callback(request, *callback_args, **callback_kwargs)
  File "D:\Project\Website\staticApp\views.py", line 35, in showImages
    with open('./images/'+path, mode="rb") as f:
FileNotFoundError: [Errno 2] No such file or directory: './static/friend_02.jpg'
[2019-02-25 11:20:40,166][Thread-6:133940][task_id:django.request][log.py:228][ERROR][Internal Server Error: /assets/js/skel.min.js]
Traceback (most recent call last):
  File "D:\Project\Website\venv\lib\site-packages\django\core\handlers\exception.py", line 34, in inner
    response = get_response(request)
  File "D:\Project\Website\venv\lib\site-packages\django\core\handlers\base.py", line 126, in _get_response
    response = self.process_exception_by_middleware(e, request)
  File "D:\Project\Website\venv\lib\site-packages\django\core\handlers\base.py", line 124, in _get_response
    response = wrapped_callback(request, *callback_args, **callback_kwargs)
  File "D:\Project\Website\staticApp\views.py", line 26, in showAssets
    with open('./assets/' + path, encoding='UTF-8') as f:
FileNotFoundError: [Errno 2] No such file or directory: './static/js/skel.min.js'
[2019-02-25 11:20:40,243][Thread-6:133940][task_id:django.request][log.py:228][ERROR][Internal Server Error: /assets/js/util.js]
Traceback (most recent call last):
  File "D:\Project\Website\venv\lib\site-packages\django\core\handlers\exception.py", line 34, in inner
    response = get_response(request)
  File "D:\Project\Website\venv\lib\site-packages\django\core\handlers\base.py", line 126, in _get_response
    response = self.process_exception_by_middleware(e, request)
  File "D:\Project\Website\venv\lib\site-packages\django\core\handlers\base.py", line 124, in _get_response
    response = wrapped_callback(request, *callback_args, **callback_kwargs)
  File "D:\Project\Website\staticApp\views.py", line 26, in showAssets
    with open('./assets/' + path, encoding='UTF-8') as f:
FileNotFoundError: [Errno 2] No such file or directory: './static/js/util.js'
[2019-02-25 11:20:40,349][Thread-6:133940][task_id:django.request][log.py:228][ERROR][Internal Server Error: /assets/js/main.js]
Traceback (most recent call last):
  File "D:\Project\Website\venv\lib\site-packages\django\core\handlers\exception.py", line 34, in inner
    response = get_response(request)
  File "D:\Project\Website\venv\lib\site-packages\django\core\handlers\base.py", line 126, in _get_response
    response = self.process_exception_by_middleware(e, request)
  File "D:\Project\Website\venv\lib\site-packages\django\core\handlers\base.py", line 124, in _get_response
    response = wrapped_callback(request, *callback_args, **callback_kwargs)
  File "D:\Project\Website\staticApp\views.py", line 26, in showAssets
    with open('./assets/' + path, encoding='UTF-8') as f:
FileNotFoundError: [Errno 2] No such file or directory: './static/js/main.js'
[2019-02-25 11:20:40,396][Thread-6:133940][task_id:django.request][log.py:228][ERROR][Internal Server Error: /assets/js/prism.js]
Traceback (most recent call last):
  File "D:\Project\Website\venv\lib\site-packages\django\core\handlers\exception.py", line 34, in inner
    response = get_response(request)
  File "D:\Project\Website\venv\lib\site-packages\django\core\handlers\base.py", line 126, in _get_response
    response = self.process_exception_by_middleware(e, request)
  File "D:\Project\Website\venv\lib\site-packages\django\core\handlers\base.py", line 124, in _get_response
    response = wrapped_callback(request, *callback_args, **callback_kwargs)
  File "D:\Project\Website\staticApp\views.py", line 26, in showAssets
    with open('./assets/' + path, encoding='UTF-8') as f:
FileNotFoundError: [Errno 2] No such file or directory: './static/js/prism.js'
[2019-02-25 11:20:43,976][Thread-6:133940][task_id:django.request][log.py:228][ERROR][Internal Server Error: /assets/css/main.css]
Traceback (most recent call last):
  File "D:\Project\Website\venv\lib\site-packages\django\core\handlers\exception.py", line 34, in inner
    response = get_response(request)
  File "D:\Project\Website\venv\lib\site-packages\django\core\handlers\base.py", line 126, in _get_response
    response = self.process_exception_by_middleware(e, request)
  File "D:\Project\Website\venv\lib\site-packages\django\core\handlers\base.py", line 124, in _get_response
    response = wrapped_callback(request, *callback_args, **callback_kwargs)
  File "D:\Project\Website\staticApp\views.py", line 21, in showAssets
    with open('./assets/' + path, encoding='UTF-8') as f:
FileNotFoundError: [Errno 2] No such file or directory: './assets/css/main.css'
[2019-02-25 11:20:44,001][Thread-4:133924][task_id:django.request][log.py:228][ERROR][Internal Server Error: /assets/css/prism.css]
Traceback (most recent call last):
  File "D:\Project\Website\venv\lib\site-packages\django\core\handlers\exception.py", line 34, in inner
    response = get_response(request)
  File "D:\Project\Website\venv\lib\site-packages\django\core\handlers\base.py", line 126, in _get_response
    response = self.process_exception_by_middleware(e, request)
  File "D:\Project\Website\venv\lib\site-packages\django\core\handlers\base.py", line 124, in _get_response
    response = wrapped_callback(request, *callback_args, **callback_kwargs)
  File "D:\Project\Website\staticApp\views.py", line 21, in showAssets
    with open('./assets/' + path, encoding='UTF-8') as f:
FileNotFoundError: [Errno 2] No such file or directory: './assets/css/prism.css'
[2019-02-25 11:22:41,048][Thread-1:133520][task_id:staticApp.views][views.py:14][INFO][Accessing Page index.html with showMainPage]
[2019-02-25 11:22:42,881][Thread-4:133720][task_id:root][views.py:30][INFO][Accessing asset /fonts/fontawesome-webfont.woff2 with showAssets matched nothing.]
[2019-02-25 11:22:43,047][Thread-4:133720][task_id:django.request][log.py:228][ERROR][Internal Server Error: /assets/fonts/fontawesome-webfont.woff2]
Traceback (most recent call last):
  File "D:\Project\Website\venv\lib\site-packages\django\core\handlers\exception.py", line 34, in inner
    response = get_response(request)
  File "D:\Project\Website\venv\lib\site-packages\django\core\handlers\base.py", line 137, in _get_response
    "returned None instead." % (callback.__module__, view_name)
ValueError: The view staticApp.views.showAssets didn't return an HttpResponse object. It returned None instead.
[2019-02-25 11:22:43,176][Thread-4:133720][task_id:root][views.py:30][INFO][Accessing asset /fonts/fontawesome-webfont.woff with showAssets matched nothing.]
[2019-02-25 11:22:43,275][Thread-4:133720][task_id:django.request][log.py:228][ERROR][Internal Server Error: /assets/fonts/fontawesome-webfont.woff]
Traceback (most recent call last):
  File "D:\Project\Website\venv\lib\site-packages\django\core\handlers\exception.py", line 34, in inner
    response = get_response(request)
  File "D:\Project\Website\venv\lib\site-packages\django\core\handlers\base.py", line 137, in _get_response
    "returned None instead." % (callback.__module__, view_name)
ValueError: The view staticApp.views.showAssets didn't return an HttpResponse object. It returned None instead.
[2019-02-25 11:22:43,290][Thread-4:133720][task_id:root][views.py:30][INFO][Accessing asset /fonts/fontawesome-webfont.ttf with showAssets matched nothing.]
[2019-02-25 11:22:43,351][Thread-4:133720][task_id:django.request][log.py:228][ERROR][Internal Server Error: /assets/fonts/fontawesome-webfont.ttf]
Traceback (most recent call last):
  File "D:\Project\Website\venv\lib\site-packages\django\core\handlers\exception.py", line 34, in inner
    response = get_response(request)
  File "D:\Project\Website\venv\lib\site-packages\django\core\handlers\base.py", line 137, in _get_response
    "returned None instead." % (callback.__module__, view_name)
ValueError: The view staticApp.views.showAssets didn't return an HttpResponse object. It returned None instead.
[2019-02-25 11:30:58,842][Thread-1:132092][task_id:staticApp.views][views.py:14][INFO][Accessing Page index.html with showMainPage]
[2019-02-25 11:31:08,545][Thread-4:134856][task_id:staticApp.views][views.py:14][INFO][Accessing Page cf913e.html with showMainPage]
[2019-02-25 11:31:08,999][Thread-1:132092][task_id:django.request][log.py:228][WARNING][Not Found: /source/cf913e.cpp]
[2019-02-25 11:35:07,123][Thread-1:133008][task_id:staticApp.views][views.py:14][INFO][Accessing Page cf913e.html with showMainPage]
[2019-02-25 11:35:07,573][Thread-7:131652][task_id:django.request][log.py:228][ERROR][Internal Server Error: /source/cf913e.cpp]
Traceback (most recent call last):
  File "D:\Project\Website\venv\lib\site-packages\django\core\handlers\exception.py", line 34, in inner
    response = get_response(request)
  File "D:\Project\Website\venv\lib\site-packages\django\core\handlers\base.py", line 126, in _get_response
    response = self.process_exception_by_middleware(e, request)
  File "D:\Project\Website\venv\lib\site-packages\django\core\handlers\base.py", line 124, in _get_response
    response = wrapped_callback(request, *callback_args, **callback_kwargs)
  File "D:\Project\Website\staticApp\views.py", line 56, in showSource
    with open('./source/'+path, mode="r") as f:
FileNotFoundError: [Errno 2] No such file or directory: './source/cf913e.cpp'
[2019-02-25 11:35:25,234][Thread-7:131652][task_id:staticApp.views][views.py:14][INFO][Accessing Page cf913e.html with showMainPage]
[2019-02-25 11:46:08,841][Thread-8:128508][task_id:django.security.DisallowedHost][exception.py:77][ERROR][Invalid HTTP_HOST header: 'cqz83p.natappfree.cc'. You may need to add 'cqz83p.natappfree.cc' to ALLOWED_HOSTS.]
[2019-02-25 11:46:09,030][Thread-8:128508][task_id:django.request][log.py:228][WARNING][Bad Request: /]
[2019-02-25 11:46:10,777][Thread-9:132424][task_id:django.security.DisallowedHost][exception.py:77][ERROR][Invalid HTTP_HOST header: 'cqz83p.natappfree.cc'. You may need to add 'cqz83p.natappfree.cc' to ALLOWED_HOSTS.]
[2019-02-25 11:46:10,822][Thread-9:132424][task_id:django.request][log.py:228][WARNING][Bad Request: /favicon.ico]
[2019-02-25 11:46:44,805][Thread-1:124220][task_id:root][views.py:14][INFO][Accessing Page / with showMainPage]
[2019-02-25 11:46:45,697][Thread-3:133848][task_id:staticApp.views][views.py:14][INFO][Accessing Page index.html with showMainPage]
[2019-02-25 11:46:51,757][Thread-17:136148][task_id:django.request][log.py:228][WARNING][Not Found: /favicon.ico]
[2019-02-25 11:46:54,747][Thread-18:134428][task_id:staticApp.views][views.py:14][INFO][Accessing Page index.html with showMainPage]
[2019-02-25 11:47:12,014][Thread-22:135564][task_id:staticApp.views][views.py:14][INFO][Accessing Page index.html with showMainPage]
[2019-02-25 11:47:19,694][Thread-28:127868][task_id:staticApp.views][views.py:14][INFO][Accessing Page index.html with showMainPage]
[2019-02-25 11:47:22,154][Thread-32:133252][task_id:django.request][log.py:228][WARNING][Not Found: /favicon.ico]
[2019-02-25 11:47:41,725][Thread-33:132428][task_id:staticApp.views][views.py:14][INFO][Accessing Page cf765e.html with showMainPage]
[2019-02-25 11:47:43,276][Thread-37:131184][task_id:django.request][log.py:228][WARNING][Not Found: /favicon.ico]
[2019-02-25 16:29:07,934][Thread-1:138672][task_id:root][views.py:14][INFO][Accessing Page / with showMainPage]
[2019-02-25 16:29:07,958][Thread-1:138672][task_id:staticApp.views][views.py:14][INFO][Accessing Page index.html with showMainPage]
[2019-02-25 16:29:15,102][Thread-3:139796][task_id:django.request][log.py:228][WARNING][Not Found: /bin/jquery.js]
[2019-02-25 16:29:15,107][Thread-6:132000][task_id:django.request][log.py:228][WARNING][Not Found: /bin/bootstrap.min.css]
[2019-02-25 16:29:47,807][Thread-6:132000][task_id:django.request][log.py:228][WARNING][Not Found: /bin/bootstrap.min.css]
[2019-02-25 16:34:47,523][Thread-1:139464][task_id:django.request][log.py:228][ERROR][Internal Server Error: /bin/jquery.js]
Traceback (most recent call last):
  File "D:\Project\Website\venv\lib\site-packages\django\core\handlers\exception.py", line 34, in inner
    response = get_response(request)
  File "D:\Project\Website\venv\lib\site-packages\django\core\handlers\base.py", line 126, in _get_response
    response = self.process_exception_by_middleware(e, request)
  File "D:\Project\Website\venv\lib\site-packages\django\core\handlers\base.py", line 124, in _get_response
    response = wrapped_callback(request, *callback_args, **callback_kwargs)
  File "D:\Project\Website\staticApp\views.py", line 70, in showBin
    with open('./bin/' + path, encoding='UTF-8') as f:
FileNotFoundError: [Errno 2] No such file or directory: './bin/jquery.js'
[2019-02-25 16:34:47,525][Thread-3:139520][task_id:django.request][log.py:228][ERROR][Internal Server Error: /bin/bootstrap.min.css]
Traceback (most recent call last):
  File "D:\Project\Website\venv\lib\site-packages\django\core\handlers\exception.py", line 34, in inner
    response = get_response(request)
  File "D:\Project\Website\venv\lib\site-packages\django\core\handlers\base.py", line 126, in _get_response
    response = self.process_exception_by_middleware(e, request)
  File "D:\Project\Website\venv\lib\site-packages\django\core\handlers\base.py", line 124, in _get_response
    response = wrapped_callback(request, *callback_args, **callback_kwargs)
  File "D:\Project\Website\staticApp\views.py", line 65, in showBin
    with open('./bin/' + path, encoding='UTF-8') as f:
FileNotFoundError: [Errno 2] No such file or directory: './bin/bootstrap.min.css'
[2019-02-25 16:38:10,707][Thread-4:128244][task_id:root][views.py:74][INFO][Accessing /bootstrap.min.css.map with showBin matched nothing.]
[2019-02-25 16:38:10,749][Thread-4:128244][task_id:django.request][log.py:228][ERROR][Internal Server Error: /bin/bootstrap.min.css.map]
Traceback (most recent call last):
  File "D:\Project\Website\venv\lib\site-packages\django\core\handlers\exception.py", line 34, in inner
    response = get_response(request)
  File "D:\Project\Website\venv\lib\site-packages\django\core\handlers\base.py", line 137, in _get_response
    "returned None instead." % (callback.__module__, view_name)
ValueError: The view staticApp.views.showBin didn't return an HttpResponse object. It returned None instead.
[2019-02-25 16:38:19,099][Thread-4:128244][task_id:root][views.py:14][INFO][Accessing Page / with showMainPage]
[2019-02-25 16:38:19,103][Thread-4:128244][task_id:staticApp.views][views.py:14][INFO][Accessing Page index.html with showMainPage]
[2019-02-25 16:40:57,773][Thread-1:139464][task_id:staticApp.views][views.py:14][INFO][Accessing Page index.html with showMainPage]
[2019-02-25 16:41:39,380][Thread-5:133492][task_id:staticApp.views][views.py:14][INFO][Accessing Page index.html with showMainPage]
[2019-02-25 16:41:41,081][Thread-1:139464][task_id:staticApp.views][views.py:14][INFO][Accessing Page jsDraw.html with showMainPage]
[2019-02-25 16:41:43,809][Thread-1:139464][task_id:staticApp.views][views.py:14][INFO][Accessing Page jsDraw.html with showMainPage]
[2019-02-25 16:42:35,200][Thread-1:139464][task_id:staticApp.views][views.py:14][INFO][Accessing Page jsDraw.html with showMainPage]
[2019-02-25 16:42:43,384][Thread-1:139464][task_id:staticApp.views][views.py:14][INFO][Accessing Page cf765e.html with showMainPage]
[2019-02-26 15:27:45,494][Thread-1:221984][task_id:staticApp.views][views.py:14][INFO][Accessing Page index with showMainPage]
[2019-02-26 15:27:45,688][Thread-1:221984][task_id:django.request][log.py:228][ERROR][Internal Server Error: /s/index]
Traceback (most recent call last):
  File "D:\Project\Website\venv\lib\site-packages\django\core\handlers\exception.py", line 34, in inner
    response = get_response(request)
  File "D:\Project\Website\venv\lib\site-packages\django\core\handlers\base.py", line 126, in _get_response
    response = self.process_exception_by_middleware(e, request)
  File "D:\Project\Website\venv\lib\site-packages\django\core\handlers\base.py", line 124, in _get_response
    response = wrapped_callback(request, *callback_args, **callback_kwargs)
  File "D:\Project\Website\staticApp\views.py", line 15, in showPage
    with open('./html/' + path, encoding='UTF-8') as f:
FileNotFoundError: [Errno 2] No such file or directory: './html/index'
[2019-02-26 15:27:58,939][Thread-1:221736][task_id:root][views.py:14][INFO][Accessing Page / with showMainPage]
[2019-02-26 15:27:58,977][Thread-1:221736][task_id:staticApp.views][views.py:14][INFO][Accessing Page index.html with showMainPage]
[2019-02-26 15:28:06,593][Thread-6:220620][task_id:staticApp.views][views.py:14][INFO][Accessing Page devcloud.html with showMainPage]
[2019-02-26 15:28:13,485][Thread-6:220620][task_id:staticApp.views][views.py:14][INFO][Accessing Page cf765e.html with showMainPage]
[2019-02-26 17:16:12,305][Thread-8:223268][task_id:root][views.py:14][INFO][Accessing Page / with showMainPage]
[2019-02-26 17:16:12,339][Thread-8:223268][task_id:staticApp.views][views.py:14][INFO][Accessing Page index.html with showMainPage]
[2019-02-26 17:17:18,154][Thread-11:224024][task_id:staticApp.views][views.py:14][INFO][Accessing Page cf765e.html with showMainPage]
[2019-02-26 17:17:36,729][Thread-11:224024][task_id:staticApp.views][views.py:14][INFO][Accessing Page interest.html with showMainPage]
[2019-02-26 17:18:51,281][Thread-12:108588][task_id:staticApp.views][views.py:14][INFO][Accessing Page cf913e.html with showMainPage]
[2019-02-27 09:19:30,445][Thread-1:232296][task_id:root][views.py:14][INFO][Accessing Page / with showMainPage]
[2019-02-27 09:19:30,456][Thread-1:232296][task_id:staticApp.views][views.py:14][INFO][Accessing Page index.html with showMainPage]
[2019-02-27 09:19:32,746][Thread-5:231072][task_id:django.request][log.py:228][WARNING][Not Found: /favicon.ico]
[2019-02-27 09:19:34,835][Thread-5:231072][task_id:django.request][log.py:228][WARNING][Not Found: /captcha]
[2019-02-27 09:19:39,369][Thread-5:231072][task_id:captchaApp.views][views.py:31][INFO][['-4.jpg', '0.5.jpg', '11.jpg', '1120.jpg', '14.75.jpg', '19.jpg', '2-2ln2.jpg', '24.jpg', '6.jpg', 'ln2.jpg', 'n.jpg']]
[2019-02-27 09:19:39,497][Thread-5:231072][task_id:django.request][log.py:228][ERROR][Internal Server Error: /captcha/index]
Traceback (most recent call last):
  File "D:\Project\Website\venv\lib\site-packages\django\core\handlers\exception.py", line 34, in inner
    response = get_response(request)
  File "D:\Project\Website\venv\lib\site-packages\django\core\handlers\base.py", line 137, in _get_response
    "returned None instead." % (callback.__module__, view_name)
ValueError: The view captchaApp.views.showIndex didn't return an HttpResponse object. It returned None instead.
[2019-02-27 14:03:14,716][Thread-1:237904][task_id:root][views.py:14][INFO][Accessing Page / with showMainPage]
[2019-02-27 14:03:14,738][Thread-1:237904][task_id:staticApp.views][views.py:14][INFO][Accessing Page index.html with showMainPage]
[2019-02-27 14:03:18,139][Thread-5:142300][task_id:django.request][log.py:228][WARNING][Not Found: /favicon.ico]
[2019-02-27 14:03:23,929][Thread-5:142300][task_id:django.request][log.py:228][ERROR][Internal Server Error: /captcha/index]
Traceback (most recent call last):
  File "D:\Project\Website\venv\lib\site-packages\django\core\handlers\exception.py", line 34, in inner
    response = get_response(request)
  File "D:\Project\Website\venv\lib\site-packages\django\core\handlers\base.py", line 137, in _get_response
    "returned None instead." % (callback.__module__, view_name)
ValueError: The view captchaApp.views.showIndex didn't return an HttpResponse object. It returned None instead.
[2019-02-27 14:05:33,547][Thread-1:115044][task_id:root][views.py:14][INFO][Accessing Page / with showMainPage]
[2019-02-27 14:05:33,565][Thread-1:115044][task_id:staticApp.views][views.py:14][INFO][Accessing Page index.html with showMainPage]
[2019-02-27 14:05:59,016][Thread-1:115044][task_id:root][views.py:74][INFO][Accessing /bootstrap.min.css.map with showBin matched nothing.]
[2019-02-27 14:05:59,060][Thread-1:115044][task_id:django.request][log.py:228][ERROR][Internal Server Error: /bin/bootstrap.min.css.map]
Traceback (most recent call last):
  File "D:\Project\Website\venv\lib\site-packages\django\core\handlers\exception.py", line 34, in inner
    response = get_response(request)
  File "D:\Project\Website\venv\lib\site-packages\django\core\handlers\base.py", line 137, in _get_response
    "returned None instead." % (callback.__module__, view_name)
ValueError: The view staticApp.views.showBin didn't return an HttpResponse object. It returned None instead.
[2019-02-27 14:06:02,719][Thread-3:121860][task_id:root][views.py:74][INFO][Accessing /bootstrap.min.css.map with showBin matched nothing.]
[2019-02-27 14:06:02,785][Thread-3:121860][task_id:django.request][log.py:228][ERROR][Internal Server Error: /bin/bootstrap.min.css.map]
Traceback (most recent call last):
  File "D:\Project\Website\venv\lib\site-packages\django\core\handlers\exception.py", line 34, in inner
    response = get_response(request)
  File "D:\Project\Website\venv\lib\site-packages\django\core\handlers\base.py", line 137, in _get_response
    "returned None instead." % (callback.__module__, view_name)
ValueError: The view staticApp.views.showBin didn't return an HttpResponse object. It returned None instead.
[2019-02-27 14:08:46,481][Thread-1:237192][task_id:root][views.py:74][INFO][Accessing /bootstrap.min.css.map with showBin matched nothing.]
[2019-02-27 14:08:46,569][Thread-1:237192][task_id:django.request][log.py:228][ERROR][Internal Server Error: /bin/bootstrap.min.css.map]
Traceback (most recent call last):
  File "D:\Project\Website\venv\lib\site-packages\django\core\handlers\exception.py", line 34, in inner
    response = get_response(request)
  File "D:\Project\Website\venv\lib\site-packages\django\core\handlers\base.py", line 137, in _get_response
    "returned None instead." % (callback.__module__, view_name)
ValueError: The view staticApp.views.showBin didn't return an HttpResponse object. It returned None instead.
[2019-02-27 14:12:04,140][Thread-3:241268][task_id:root][views.py:74][INFO][Accessing /bootstrap.min.css.map with showBin matched nothing.]
[2019-02-27 14:12:04,205][Thread-3:241268][task_id:django.request][log.py:228][ERROR][Internal Server Error: /bin/bootstrap.min.css.map]
Traceback (most recent call last):
  File "D:\Project\Website\venv\lib\site-packages\django\core\handlers\exception.py", line 34, in inner
    response = get_response(request)
  File "D:\Project\Website\venv\lib\site-packages\django\core\handlers\base.py", line 137, in _get_response
    "returned None instead." % (callback.__module__, view_name)
ValueError: The view staticApp.views.showBin didn't return an HttpResponse object. It returned None instead.
[2019-02-27 14:15:09,928][Thread-1:223220][task_id:root][views.py:74][INFO][Accessing /bootstrap.min.css.map with showBin matched nothing.]
[2019-02-27 14:15:10,014][Thread-1:223220][task_id:django.request][log.py:228][ERROR][Internal Server Error: /bin/bootstrap.min.css.map]
Traceback (most recent call last):
  File "D:\Project\Website\venv\lib\site-packages\django\core\handlers\exception.py", line 34, in inner
    response = get_response(request)
  File "D:\Project\Website\venv\lib\site-packages\django\core\handlers\base.py", line 137, in _get_response
    "returned None instead." % (callback.__module__, view_name)
ValueError: The view staticApp.views.showBin didn't return an HttpResponse object. It returned None instead.
[2019-02-27 14:21:49,388][Thread-3:148184][task_id:root][views.py:74][INFO][Accessing /bootstrap.min.css.map with showBin matched nothing.]
[2019-02-27 14:21:49,450][Thread-1:227200][task_id:captchaApp.views][views.py:26][INFO][None]
[2019-02-27 14:21:49,449][Thread-3:148184][task_id:django.request][log.py:228][ERROR][Internal Server Error: /bin/bootstrap.min.css.map]
Traceback (most recent call last):
  File "D:\Project\Website\venv\lib\site-packages\django\core\handlers\exception.py", line 34, in inner
    response = get_response(request)
  File "D:\Project\Website\venv\lib\site-packages\django\core\handlers\base.py", line 137, in _get_response
    "returned None instead." % (callback.__module__, view_name)
ValueError: The view staticApp.views.showBin didn't return an HttpResponse object. It returned None instead.
[2019-02-27 14:23:08,963][Thread-3:242332][task_id:root][views.py:74][INFO][Accessing /bootstrap.min.css.map with showBin matched nothing.]
[2019-02-27 14:23:09,020][Thread-1:242328][task_id:captchaApp.views][views.py:26][INFO][None]
[2019-02-27 14:23:09,030][Thread-3:242332][task_id:django.request][log.py:228][ERROR][Internal Server Error: /bin/bootstrap.min.css.map]
Traceback (most recent call last):
  File "D:\Project\Website\venv\lib\site-packages\django\core\handlers\exception.py", line 34, in inner
    response = get_response(request)
  File "D:\Project\Website\venv\lib\site-packages\django\core\handlers\base.py", line 137, in _get_response
    "returned None instead." % (callback.__module__, view_name)
ValueError: The view staticApp.views.showBin didn't return an HttpResponse object. It returned None instead.
[2019-02-27 14:23:57,052][Thread-3:234564][task_id:root][views.py:74][INFO][Accessing /bootstrap.min.css.map with showBin matched nothing.]
[2019-02-27 14:23:57,119][Thread-1:240532][task_id:captchaApp.views][views.py:26][INFO][jntwa5tbhfn]
[2019-02-27 14:23:57,126][Thread-3:234564][task_id:django.request][log.py:228][ERROR][Internal Server Error: /bin/bootstrap.min.css.map]
Traceback (most recent call last):
  File "D:\Project\Website\venv\lib\site-packages\django\core\handlers\exception.py", line 34, in inner
    response = get_response(request)
  File "D:\Project\Website\venv\lib\site-packages\django\core\handlers\base.py", line 137, in _get_response
    "returned None instead." % (callback.__module__, view_name)
ValueError: The view staticApp.views.showBin didn't return an HttpResponse object. It returned None instead.
[2019-02-27 14:23:57,228][Thread-1:240532][task_id:django.request][log.py:228][ERROR][Internal Server Error: /captcha/get]
Traceback (most recent call last):
  File "D:\Project\Website\venv\lib\site-packages\django\core\handlers\exception.py", line 34, in inner
    response = get_response(request)
  File "D:\Project\Website\venv\lib\site-packages\django\core\handlers\base.py", line 126, in _get_response
    response = self.process_exception_by_middleware(e, request)
  File "D:\Project\Website\venv\lib\site-packages\django\core\handlers\base.py", line 124, in _get_response
    response = wrapped_callback(request, *callback_args, **callback_kwargs)
  File "D:\Project\Website\captchaApp\views.py", line 41, in getCaptcha
    sha.update(ans)
TypeError: Unicode-objects must be encoded before hashing
[2019-02-27 14:26:04,068][Thread-3:242372][task_id:root][views.py:74][INFO][Accessing /bootstrap.min.css.map with showBin matched nothing.]
[2019-02-27 14:26:04,138][Thread-3:242372][task_id:django.request][log.py:228][ERROR][Internal Server Error: /bin/bootstrap.min.css.map]
Traceback (most recent call last):
  File "D:\Project\Website\venv\lib\site-packages\django\core\handlers\exception.py", line 34, in inner
    response = get_response(request)
  File "D:\Project\Website\venv\lib\site-packages\django\core\handlers\base.py", line 137, in _get_response
    "returned None instead." % (callback.__module__, view_name)
ValueError: The view staticApp.views.showBin didn't return an HttpResponse object. It returned None instead.
[2019-02-27 14:26:04,357][Thread-1:239652][task_id:django.request][log.py:228][ERROR][Internal Server Error: /captcha/get]
Traceback (most recent call last):
  File "D:\Project\Website\venv\lib\site-packages\django\db\backends\utils.py", line 85, in _execute
    return self.cursor.execute(sql, params)
  File "D:\Project\Website\venv\lib\site-packages\django\db\backends\sqlite3\base.py", line 298, in execute
    return Database.Cursor.execute(self, query, params)
sqlite3.OperationalError: no such table: captchaApp_captcharecord

The above exception was the direct cause of the following exception:

Traceback (most recent call last):
  File "D:\Project\Website\venv\lib\site-packages\django\core\handlers\exception.py", line 34, in inner
    response = get_response(request)
  File "D:\Project\Website\venv\lib\site-packages\django\core\handlers\base.py", line 126, in _get_response
    response = self.process_exception_by_middleware(e, request)
  File "D:\Project\Website\venv\lib\site-packages\django\core\handlers\base.py", line 124, in _get_response
    response = wrapped_callback(request, *callback_args, **callback_kwargs)
  File "D:\Project\Website\captchaApp\views.py", line 41, in getCaptcha
    cr.save()
  File "D:\Project\Website\venv\lib\site-packages\django\db\models\base.py", line 718, in save
    force_update=force_update, update_fields=update_fields)
  File "D:\Project\Website\venv\lib\site-packages\django\db\models\base.py", line 748, in save_base
    updated = self._save_table(raw, cls, force_insert, force_update, using, update_fields)
  File "D:\Project\Website\venv\lib\site-packages\django\db\models\base.py", line 831, in _save_table
    result = self._do_insert(cls._base_manager, using, fields, update_pk, raw)
  File "D:\Project\Website\venv\lib\site-packages\django\db\models\base.py", line 869, in _do_insert
    using=using, raw=raw)
  File "D:\Project\Website\venv\lib\site-packages\django\db\models\manager.py", line 82, in manager_method
    return getattr(self.get_queryset(), name)(*args, **kwargs)
  File "D:\Project\Website\venv\lib\site-packages\django\db\models\query.py", line 1136, in _insert
    return query.get_compiler(using=using).execute_sql(return_id)
  File "D:\Project\Website\venv\lib\site-packages\django\db\models\sql\compiler.py", line 1289, in execute_sql
    cursor.execute(sql, params)
  File "D:\Project\Website\venv\lib\site-packages\django\db\backends\utils.py", line 100, in execute
    return super().execute(sql, params)
  File "D:\Project\Website\venv\lib\site-packages\django\db\backends\utils.py", line 68, in execute
    return self._execute_with_wrappers(sql, params, many=False, executor=self._execute)
  File "D:\Project\Website\venv\lib\site-packages\django\db\backends\utils.py", line 77, in _execute_with_wrappers
    return executor(sql, params, many, context)
  File "D:\Project\Website\venv\lib\site-packages\django\db\backends\utils.py", line 85, in _execute
    return self.cursor.execute(sql, params)
  File "D:\Project\Website\venv\lib\site-packages\django\db\utils.py", line 89, in __exit__
    raise dj_exc_value.with_traceback(traceback) from exc_value
  File "D:\Project\Website\venv\lib\site-packages\django\db\backends\utils.py", line 85, in _execute
    return self.cursor.execute(sql, params)
  File "D:\Project\Website\venv\lib\site-packages\django\db\backends\sqlite3\base.py", line 298, in execute
    return Database.Cursor.execute(self, query, params)
django.db.utils.OperationalError: no such table: captchaApp_captcharecord
[2019-02-27 14:37:50,525][Thread-3:243896][task_id:root][views.py:74][INFO][Accessing /bootstrap.min.css.map with showBin matched nothing.]
[2019-02-27 14:37:50,604][Thread-3:243896][task_id:django.request][log.py:228][ERROR][Internal Server Error: /bin/bootstrap.min.css.map]
Traceback (most recent call last):
  File "D:\Project\Website\venv\lib\site-packages\django\core\handlers\exception.py", line 34, in inner
    response = get_response(request)
  File "D:\Project\Website\venv\lib\site-packages\django\core\handlers\base.py", line 137, in _get_response
    "returned None instead." % (callback.__module__, view_name)
ValueError: The view staticApp.views.showBin didn't return an HttpResponse object. It returned None instead.
[2019-02-27 14:37:50,654][Thread-1:243972][task_id:django.request][log.py:228][ERROR][Internal Server Error: /captcha/get]
Traceback (most recent call last):
  File "D:\Project\Website\venv\lib\site-packages\django\db\backends\utils.py", line 85, in _execute
    return self.cursor.execute(sql, params)
  File "D:\Project\Website\venv\lib\site-packages\django\db\backends\sqlite3\base.py", line 298, in execute
    return Database.Cursor.execute(self, query, params)
sqlite3.IntegrityError: NOT NULL constraint failed: captchaApp_captcharecord.user

The above exception was the direct cause of the following exception:

Traceback (most recent call last):
  File "D:\Project\Website\venv\lib\site-packages\django\core\handlers\exception.py", line 34, in inner
    response = get_response(request)
  File "D:\Project\Website\venv\lib\site-packages\django\core\handlers\base.py", line 126, in _get_response
    response = self.process_exception_by_middleware(e, request)
  File "D:\Project\Website\venv\lib\site-packages\django\core\handlers\base.py", line 124, in _get_response
    response = wrapped_callback(request, *callback_args, **callback_kwargs)
  File "D:\Project\Website\captchaApp\views.py", line 41, in getCaptcha
    cr.save()
  File "D:\Project\Website\venv\lib\site-packages\django\db\models\base.py", line 718, in save
    force_update=force_update, update_fields=update_fields)
  File "D:\Project\Website\venv\lib\site-packages\django\db\models\base.py", line 748, in save_base
    updated = self._save_table(raw, cls, force_insert, force_update, using, update_fields)
  File "D:\Project\Website\venv\lib\site-packages\django\db\models\base.py", line 831, in _save_table
    result = self._do_insert(cls._base_manager, using, fields, update_pk, raw)
  File "D:\Project\Website\venv\lib\site-packages\django\db\models\base.py", line 869, in _do_insert
    using=using, raw=raw)
  File "D:\Project\Website\venv\lib\site-packages\django\db\models\manager.py", line 82, in manager_method
    return getattr(self.get_queryset(), name)(*args, **kwargs)
  File "D:\Project\Website\venv\lib\site-packages\django\db\models\query.py", line 1136, in _insert
    return query.get_compiler(using=using).execute_sql(return_id)
  File "D:\Project\Website\venv\lib\site-packages\django\db\models\sql\compiler.py", line 1289, in execute_sql
    cursor.execute(sql, params)
  File "D:\Project\Website\venv\lib\site-packages\django\db\backends\utils.py", line 100, in execute
    return super().execute(sql, params)
  File "D:\Project\Website\venv\lib\site-packages\django\db\backends\utils.py", line 68, in execute
    return self._execute_with_wrappers(sql, params, many=False, executor=self._execute)
  File "D:\Project\Website\venv\lib\site-packages\django\db\backends\utils.py", line 77, in _execute_with_wrappers
    return executor(sql, params, many, context)
  File "D:\Project\Website\venv\lib\site-packages\django\db\backends\utils.py", line 85, in _execute
    return self.cursor.execute(sql, params)
  File "D:\Project\Website\venv\lib\site-packages\django\db\utils.py", line 89, in __exit__
    raise dj_exc_value.with_traceback(traceback) from exc_value
  File "D:\Project\Website\venv\lib\site-packages\django\db\backends\utils.py", line 85, in _execute
    return self.cursor.execute(sql, params)
  File "D:\Project\Website\venv\lib\site-packages\django\db\backends\sqlite3\base.py", line 298, in execute
    return Database.Cursor.execute(self, query, params)
django.db.utils.IntegrityError: NOT NULL constraint failed: captchaApp_captcharecord.user
[2019-02-27 14:40:19,104][Thread-3:243520][task_id:root][views.py:74][INFO][Accessing /bootstrap.min.css.map with showBin matched nothing.]
[2019-02-27 14:40:19,182][Thread-3:243520][task_id:django.request][log.py:228][ERROR][Internal Server Error: /bin/bootstrap.min.css.map]
Traceback (most recent call last):
  File "D:\Project\Website\venv\lib\site-packages\django\core\handlers\exception.py", line 34, in inner
    response = get_response(request)
  File "D:\Project\Website\venv\lib\site-packages\django\core\handlers\base.py", line 137, in _get_response
    "returned None instead." % (callback.__module__, view_name)
ValueError: The view staticApp.views.showBin didn't return an HttpResponse object. It returned None instead.
[2019-02-27 14:40:19,242][Thread-1:4936][task_id:django.request][log.py:228][ERROR][Internal Server Error: /captcha/get]
Traceback (most recent call last):
  File "D:\Project\Website\venv\lib\site-packages\django\db\backends\utils.py", line 85, in _execute
    return self.cursor.execute(sql, params)
  File "D:\Project\Website\venv\lib\site-packages\django\db\backends\sqlite3\base.py", line 298, in execute
    return Database.Cursor.execute(self, query, params)
sqlite3.IntegrityError: NOT NULL constraint failed: captchaApp_captcharecord.user

The above exception was the direct cause of the following exception:

Traceback (most recent call last):
  File "D:\Project\Website\venv\lib\site-packages\django\core\handlers\exception.py", line 34, in inner
    response = get_response(request)
  File "D:\Project\Website\venv\lib\site-packages\django\core\handlers\base.py", line 126, in _get_response
    response = self.process_exception_by_middleware(e, request)
  File "D:\Project\Website\venv\lib\site-packages\django\core\handlers\base.py", line 124, in _get_response
    response = wrapped_callback(request, *callback_args, **callback_kwargs)
  File "D:\Project\Website\captchaApp\views.py", line 41, in getCaptcha
    cr.save()
  File "D:\Project\Website\venv\lib\site-packages\django\db\models\base.py", line 718, in save
    force_update=force_update, update_fields=update_fields)
  File "D:\Project\Website\venv\lib\site-packages\django\db\models\base.py", line 748, in save_base
    updated = self._save_table(raw, cls, force_insert, force_update, using, update_fields)
  File "D:\Project\Website\venv\lib\site-packages\django\db\models\base.py", line 831, in _save_table
    result = self._do_insert(cls._base_manager, using, fields, update_pk, raw)
  File "D:\Project\Website\venv\lib\site-packages\django\db\models\base.py", line 869, in _do_insert
    using=using, raw=raw)
  File "D:\Project\Website\venv\lib\site-packages\django\db\models\manager.py", line 82, in manager_method
    return getattr(self.get_queryset(), name)(*args, **kwargs)
  File "D:\Project\Website\venv\lib\site-packages\django\db\models\query.py", line 1136, in _insert
    return query.get_compiler(using=using).execute_sql(return_id)
  File "D:\Project\Website\venv\lib\site-packages\django\db\models\sql\compiler.py", line 1289, in execute_sql
    cursor.execute(sql, params)
  File "D:\Project\Website\venv\lib\site-packages\django\db\backends\utils.py", line 100, in execute
    return super().execute(sql, params)
  File "D:\Project\Website\venv\lib\site-packages\django\db\backends\utils.py", line 68, in execute
    return self._execute_with_wrappers(sql, params, many=False, executor=self._execute)
  File "D:\Project\Website\venv\lib\site-packages\django\db\backends\utils.py", line 77, in _execute_with_wrappers
    return executor(sql, params, many, context)
  File "D:\Project\Website\venv\lib\site-packages\django\db\backends\utils.py", line 85, in _execute
    return self.cursor.execute(sql, params)
  File "D:\Project\Website\venv\lib\site-packages\django\db\utils.py", line 89, in __exit__
    raise dj_exc_value.with_traceback(traceback) from exc_value
  File "D:\Project\Website\venv\lib\site-packages\django\db\backends\utils.py", line 85, in _execute
    return self.cursor.execute(sql, params)
  File "D:\Project\Website\venv\lib\site-packages\django\db\backends\sqlite3\base.py", line 298, in execute
    return Database.Cursor.execute(self, query, params)
django.db.utils.IntegrityError: NOT NULL constraint failed: captchaApp_captcharecord.user
[2019-02-27 14:41:11,433][Thread-3:229484][task_id:root][views.py:74][INFO][Accessing /bootstrap.min.css.map with showBin matched nothing.]
[2019-02-27 14:41:11,499][Thread-3:229484][task_id:django.request][log.py:228][ERROR][Internal Server Error: /bin/bootstrap.min.css.map]
Traceback (most recent call last):
  File "D:\Project\Website\venv\lib\site-packages\django\core\handlers\exception.py", line 34, in inner
    response = get_response(request)
  File "D:\Project\Website\venv\lib\site-packages\django\core\handlers\base.py", line 137, in _get_response
    "returned None instead." % (callback.__module__, view_name)
ValueError: The view staticApp.views.showBin didn't return an HttpResponse object. It returned None instead.
[2019-02-27 14:41:13,360][Thread-1:244352][task_id:django.request][log.py:228][WARNING][Not Found: /captcha/captcha/ln2.jpg]
[2019-02-27 14:49:37,155][Thread-1:243624][task_id:root][views.py:14][INFO][Accessing Page / with showMainPage]
[2019-02-27 14:49:37,196][Thread-1:243624][task_id:staticApp.views][views.py:14][INFO][Accessing Page index.html with showMainPage]
[2019-02-27 14:51:47,262][Thread-3:242140][task_id:root][views.py:74][INFO][Accessing /bootstrap.min.css.map with showBin matched nothing.]
[2019-02-27 14:51:47,330][Thread-3:242140][task_id:django.request][log.py:228][ERROR][Internal Server Error: /bin/bootstrap.min.css.map]
Traceback (most recent call last):
  File "D:\Project\Website\venv\lib\site-packages\django\core\handlers\exception.py", line 34, in inner
    response = get_response(request)
  File "D:\Project\Website\venv\lib\site-packages\django\core\handlers\base.py", line 137, in _get_response
    "returned None instead." % (callback.__module__, view_name)
ValueError: The view staticApp.views.showBin didn't return an HttpResponse object. It returned None instead.
[2019-02-27 14:51:48,840][Thread-1:242416][task_id:django.request][log.py:228][WARNING][Not Found: /captcha/img/dqoeljeq6q4]
[2019-02-27 14:52:22,358][Thread-1:243008][task_id:root][views.py:74][INFO][Accessing /bootstrap.min.css.map with showBin matched nothing.]
[2019-02-27 14:52:22,438][Thread-1:243008][task_id:django.request][log.py:228][ERROR][Internal Server Error: /bin/bootstrap.min.css.map]
Traceback (most recent call last):
  File "D:\Project\Website\venv\lib\site-packages\django\core\handlers\exception.py", line 34, in inner
    response = get_response(request)
  File "D:\Project\Website\venv\lib\site-packages\django\core\handlers\base.py", line 137, in _get_response
    "returned None instead." % (callback.__module__, view_name)
ValueError: The view staticApp.views.showBin didn't return an HttpResponse object. It returned None instead.
[2019-02-27 14:54:32,987][Thread-1:243544][task_id:root][views.py:74][INFO][Accessing /bootstrap.min.css.map with showBin matched nothing.]
[2019-02-27 14:54:33,059][Thread-1:243544][task_id:django.request][log.py:228][ERROR][Internal Server Error: /bin/bootstrap.min.css.map]
Traceback (most recent call last):
  File "D:\Project\Website\venv\lib\site-packages\django\core\handlers\exception.py", line 34, in inner
    response = get_response(request)
  File "D:\Project\Website\venv\lib\site-packages\django\core\handlers\base.py", line 137, in _get_response
    "returned None instead." % (callback.__module__, view_name)
ValueError: The view staticApp.views.showBin didn't return an HttpResponse object. It returned None instead.
[2019-02-27 14:56:51,831][Thread-3:242912][task_id:root][views.py:74][INFO][Accessing /bootstrap.min.css.map with showBin matched nothing.]
[2019-02-27 14:56:51,886][Thread-3:242912][task_id:django.request][log.py:228][ERROR][Internal Server Error: /bin/bootstrap.min.css.map]
Traceback (most recent call last):
  File "D:\Project\Website\venv\lib\site-packages\django\core\handlers\exception.py", line 34, in inner
    response = get_response(request)
  File "D:\Project\Website\venv\lib\site-packages\django\core\handlers\base.py", line 137, in _get_response
    "returned None instead." % (callback.__module__, view_name)
ValueError: The view staticApp.views.showBin didn't return an HttpResponse object. It returned None instead.
[2019-02-27 14:56:56,359][Thread-1:239112][task_id:root][views.py:74][INFO][Accessing /bootstrap.min.css.map with showBin matched nothing.]
[2019-02-27 14:56:56,430][Thread-1:239112][task_id:django.request][log.py:228][ERROR][Internal Server Error: /bin/bootstrap.min.css.map]
Traceback (most recent call last):
  File "D:\Project\Website\venv\lib\site-packages\django\core\handlers\exception.py", line 34, in inner
    response = get_response(request)
  File "D:\Project\Website\venv\lib\site-packages\django\core\handlers\base.py", line 137, in _get_response
    "returned None instead." % (callback.__module__, view_name)
ValueError: The view staticApp.views.showBin didn't return an HttpResponse object. It returned None instead.
[2019-02-27 14:57:54,860][Thread-1:239112][task_id:root][views.py:74][INFO][Accessing /bootstrap.min.css.map with showBin matched nothing.]
[2019-02-27 14:57:54,904][Thread-1:239112][task_id:django.request][log.py:228][ERROR][Internal Server Error: /bin/bootstrap.min.css.map]
Traceback (most recent call last):
  File "D:\Project\Website\venv\lib\site-packages\django\core\handlers\exception.py", line 34, in inner
    response = get_response(request)
  File "D:\Project\Website\venv\lib\site-packages\django\core\handlers\base.py", line 137, in _get_response
    "returned None instead." % (callback.__module__, view_name)
ValueError: The view staticApp.views.showBin didn't return an HttpResponse object. It returned None instead.
[2019-02-27 14:58:04,675][Thread-3:242188][task_id:root][views.py:74][INFO][Accessing /bootstrap.min.css.map with showBin matched nothing.]
[2019-02-27 14:58:04,741][Thread-3:242188][task_id:django.request][log.py:228][ERROR][Internal Server Error: /bin/bootstrap.min.css.map]
Traceback (most recent call last):
  File "D:\Project\Website\venv\lib\site-packages\django\core\handlers\exception.py", line 34, in inner
    response = get_response(request)
  File "D:\Project\Website\venv\lib\site-packages\django\core\handlers\base.py", line 137, in _get_response
    "returned None instead." % (callback.__module__, view_name)
ValueError: The view staticApp.views.showBin didn't return an HttpResponse object. It returned None instead.
[2019-02-27 14:58:57,780][Thread-3:229572][task_id:root][views.py:74][INFO][Accessing /bootstrap.min.css.map with showBin matched nothing.]
[2019-02-27 14:58:57,858][Thread-3:229572][task_id:django.request][log.py:228][ERROR][Internal Server Error: /bin/bootstrap.min.css.map]
Traceback (most recent call last):
  File "D:\Project\Website\venv\lib\site-packages\django\core\handlers\exception.py", line 34, in inner
    response = get_response(request)
  File "D:\Project\Website\venv\lib\site-packages\django\core\handlers\base.py", line 137, in _get_response
    "returned None instead." % (callback.__module__, view_name)
ValueError: The view staticApp.views.showBin didn't return an HttpResponse object. It returned None instead.
[2019-02-27 14:59:53,503][Thread-1:231764][task_id:root][views.py:74][INFO][Accessing /bootstrap.min.css.map with showBin matched nothing.]
[2019-02-27 14:59:53,573][Thread-1:231764][task_id:django.request][log.py:228][ERROR][Internal Server Error: /bin/bootstrap.min.css.map]
Traceback (most recent call last):
  File "D:\Project\Website\venv\lib\site-packages\django\core\handlers\exception.py", line 34, in inner
    response = get_response(request)
  File "D:\Project\Website\venv\lib\site-packages\django\core\handlers\base.py", line 137, in _get_response
    "returned None instead." % (callback.__module__, view_name)
ValueError: The view staticApp.views.showBin didn't return an HttpResponse object. It returned None instead.
[2019-02-27 15:02:43,760][Thread-3:232144][task_id:root][views.py:74][INFO][Accessing /bootstrap.min.css.map with showBin matched nothing.]
[2019-02-27 15:02:43,826][Thread-3:232144][task_id:django.request][log.py:228][ERROR][Internal Server Error: /bin/bootstrap.min.css.map]
Traceback (most recent call last):
  File "D:\Project\Website\venv\lib\site-packages\django\core\handlers\exception.py", line 34, in inner
    response = get_response(request)
  File "D:\Project\Website\venv\lib\site-packages\django\core\handlers\base.py", line 137, in _get_response
    "returned None instead." % (callback.__module__, view_name)
ValueError: The view staticApp.views.showBin didn't return an HttpResponse object. It returned None instead.
[2019-02-27 15:03:00,429][Thread-3:232144][task_id:root][views.py:74][INFO][Accessing /bootstrap.min.css.map with showBin matched nothing.]
[2019-02-27 15:03:00,507][Thread-3:232144][task_id:django.request][log.py:228][ERROR][Internal Server Error: /bin/bootstrap.min.css.map]
Traceback (most recent call last):
  File "D:\Project\Website\venv\lib\site-packages\django\core\handlers\exception.py", line 34, in inner
    response = get_response(request)
  File "D:\Project\Website\venv\lib\site-packages\django\core\handlers\base.py", line 137, in _get_response
    "returned None instead." % (callback.__module__, view_name)
ValueError: The view staticApp.views.showBin didn't return an HttpResponse object. It returned None instead.
[2019-02-27 15:37:15,886][Thread-3:125556][task_id:django.request][log.py:228][WARNING][Not Found: /captcha/]
[2019-02-27 15:37:19,630][Thread-3:125556][task_id:root][views.py:74][INFO][Accessing /bootstrap.min.css.map with showBin matched nothing.]
[2019-02-27 15:37:19,713][Thread-3:125556][task_id:django.request][log.py:228][ERROR][Internal Server Error: /bin/bootstrap.min.css.map]
Traceback (most recent call last):
  File "D:\Project\Website\venv\lib\site-packages\django\core\handlers\exception.py", line 34, in inner
    response = get_response(request)
  File "D:\Project\Website\venv\lib\site-packages\django\core\handlers\base.py", line 137, in _get_response
    "returned None instead." % (callback.__module__, view_name)
ValueError: The view staticApp.views.showBin didn't return an HttpResponse object. It returned None instead.
[2019-02-27 15:37:36,673][Thread-3:245932][task_id:root][views.py:74][INFO][Accessing /bootstrap.min.css.map with showBin matched nothing.]
[2019-02-27 15:37:36,731][Thread-3:245932][task_id:django.request][log.py:228][ERROR][Internal Server Error: /bin/bootstrap.min.css.map]
Traceback (most recent call last):
  File "D:\Project\Website\venv\lib\site-packages\django\core\handlers\exception.py", line 34, in inner
    response = get_response(request)
  File "D:\Project\Website\venv\lib\site-packages\django\core\handlers\base.py", line 137, in _get_response
    "returned None instead." % (callback.__module__, view_name)
ValueError: The view staticApp.views.showBin didn't return an HttpResponse object. It returned None instead.
[2019-02-27 15:38:32,839][Thread-3:246192][task_id:root][views.py:74][INFO][Accessing /bootstrap.min.css.map with showBin matched nothing.]
[2019-02-27 15:38:32,896][Thread-3:246192][task_id:django.request][log.py:228][ERROR][Internal Server Error: /bin/bootstrap.min.css.map]
Traceback (most recent call last):
  File "D:\Project\Website\venv\lib\site-packages\django\core\handlers\exception.py", line 34, in inner
    response = get_response(request)
  File "D:\Project\Website\venv\lib\site-packages\django\core\handlers\base.py", line 137, in _get_response
    "returned None instead." % (callback.__module__, view_name)
ValueError: The view staticApp.views.showBin didn't return an HttpResponse object. It returned None instead.
[2019-02-27 15:49:17,420][Thread-7:245404][task_id:root][views.py:74][INFO][Accessing /bootstrap.min.css.map with showBin matched nothing.]
[2019-02-27 15:49:17,472][Thread-7:245404][task_id:django.request][log.py:228][ERROR][Internal Server Error: /bin/bootstrap.min.css.map]
Traceback (most recent call last):
  File "D:\Project\Website\venv\lib\site-packages\django\core\handlers\exception.py", line 34, in inner
    response = get_response(request)
  File "D:\Project\Website\venv\lib\site-packages\django\core\handlers\base.py", line 137, in _get_response
    "returned None instead." % (callback.__module__, view_name)
ValueError: The view staticApp.views.showBin didn't return an HttpResponse object. It returned None instead.
[2019-02-27 15:49:18,986][Thread-9:247352][task_id:django.request][log.py:228][WARNING][Not Found: /favicon.ico]
[2019-02-27 16:13:32,527][Thread-39:250824][task_id:django.request][log.py:228][WARNING][Not Found: /favicon.ico]
[2019-02-27 16:14:51,417][Thread-40:243112][task_id:root][views.py:74][INFO][Accessing /bootstrap.min.css.map with showBin matched nothing.]
[2019-02-27 16:14:51,473][Thread-40:243112][task_id:django.request][log.py:228][ERROR][Internal Server Error: /bin/bootstrap.min.css.map]
Traceback (most recent call last):
  File "D:\Project\Website\venv\lib\site-packages\django\core\handlers\exception.py", line 34, in inner
    response = get_response(request)
  File "D:\Project\Website\venv\lib\site-packages\django\core\handlers\base.py", line 137, in _get_response
    "returned None instead." % (callback.__module__, view_name)
ValueError: The view staticApp.views.showBin didn't return an HttpResponse object. It returned None instead.
[2019-02-27 17:46:15,526][Thread-1:254260][task_id:django.request][log.py:228][ERROR][Internal Server Error: /captcha/index]
Traceback (most recent call last):
  File "D:\Project\Website\venv\lib\site-packages\django\core\handlers\exception.py", line 34, in inner
    response = get_response(request)
  File "D:\Project\Website\venv\lib\site-packages\django\core\handlers\base.py", line 126, in _get_response
    response = self.process_exception_by_middleware(e, request)
  File "D:\Project\Website\venv\lib\site-packages\django\core\handlers\base.py", line 124, in _get_response
    response = wrapped_callback(request, *callback_args, **callback_kwargs)
  File "D:\Project\Website\captchaApp\views.py", line 32, in showIndex
    return HttpResponse(render(context,request))
  File "D:\Project\Website\venv\lib\site-packages\django\shortcuts.py", line 36, in render
    content = loader.render_to_string(template_name, context, request, using=using)
  File "D:\Project\Website\venv\lib\site-packages\django\template\loader.py", line 61, in render_to_string
    template = get_template(template_name, using=using)
  File "D:\Project\Website\venv\lib\site-packages\django\template\loader.py", line 15, in get_template
    return engine.get_template(template_name)
  File "D:\Project\Website\venv\lib\site-packages\django\template\backends\django.py", line 34, in get_template
    return Template(self.engine.get_template(template_name), self)
  File "D:\Project\Website\venv\lib\site-packages\django\template\engine.py", line 144, in get_template
    template, origin = self.find_template(template_name)
  File "D:\Project\Website\venv\lib\site-packages\django\template\engine.py", line 126, in find_template
    template = loader.get_template(name, skip=skip)
  File "D:\Project\Website\venv\lib\site-packages\django\template\loaders\base.py", line 24, in get_template
    contents = self.get_contents(origin)
  File "D:\Project\Website\venv\lib\site-packages\django\template\loaders\filesystem.py", line 23, in get_contents
    with open(origin.name, encoding=self.engine.file_charset) as fp:
OSError: [Errno 22] Invalid argument: "D:\\Project\\Website\\templates\\<WSGIRequest: GET '\\captcha\\index?tdsourcetag=s_pctim_aiomsg'>"
[2019-02-27 18:15:37,256][Thread-5:256332][task_id:root][views.py:14][INFO][Accessing Page / with showMainPage]
[2019-02-27 18:15:37,365][Thread-6:251892][task_id:root][views.py:14][INFO][Accessing Page / with showMainPage]
[2019-02-27 18:15:37,371][Thread-7:252956][task_id:root][views.py:14][INFO][Accessing Page / with showMainPage]
[2019-02-27 18:15:37,394][Thread-8:253732][task_id:root][views.py:14][INFO][Accessing Page / with showMainPage]
[2019-02-27 18:15:38,231][Thread-10:256380][task_id:root][views.py:14][INFO][Accessing Page / with showMainPage]
[2019-02-27 18:15:38,255][Thread-12:256224][task_id:root][views.py:14][INFO][Accessing Page / with showMainPage]
[2019-02-27 18:15:38,271][Thread-13:251484][task_id:root][views.py:14][INFO][Accessing Page / with showMainPage]
[2019-02-27 18:15:38,280][Thread-14:256732][task_id:root][views.py:14][INFO][Accessing Page / with showMainPage]
[2019-02-27 18:15:39,646][Thread-16:254724][task_id:django.request][log.py:228][WARNING][Not Found: /favicon.ico]
[2019-02-27 18:15:39,686][Thread-17:253460][task_id:root][views.py:14][INFO][Accessing Page / with showMainPage]
[2019-02-27 18:15:40,301][Thread-19:253824][task_id:root][views.py:14][INFO][Accessing Page / with showMainPage]
[2019-02-27 19:01:26,129][Thread-1:259232][task_id:root][views.py:74][INFO][Accessing /bootstrap.min.css.map with showBin matched nothing.]
[2019-02-27 19:01:26,184][Thread-1:259232][task_id:django.request][log.py:228][ERROR][Internal Server Error: /bin/bootstrap.min.css.map]
Traceback (most recent call last):
  File "D:\Project\Website\venv\lib\site-packages\django\core\handlers\exception.py", line 34, in inner
    response = get_response(request)
  File "D:\Project\Website\venv\lib\site-packages\django\core\handlers\base.py", line 137, in _get_response
    "returned None instead." % (callback.__module__, view_name)
ValueError: The view staticApp.views.showBin didn't return an HttpResponse object. It returned None instead.
[2019-02-27 19:01:33,190][Thread-5:259728][task_id:root][views.py:74][INFO][Accessing /bootstrap.min.css.map with showBin matched nothing.]
[2019-02-27 19:01:33,240][Thread-5:259728][task_id:django.request][log.py:228][ERROR][Internal Server Error: /bin/bootstrap.min.css.map]
Traceback (most recent call last):
  File "D:\Project\Website\venv\lib\site-packages\django\core\handlers\exception.py", line 34, in inner
    response = get_response(request)
  File "D:\Project\Website\venv\lib\site-packages\django\core\handlers\base.py", line 137, in _get_response
    "returned None instead." % (callback.__module__, view_name)
ValueError: The view staticApp.views.showBin didn't return an HttpResponse object. It returned None instead.
[2019-02-27 19:04:44,393][Thread-5:255736][task_id:root][views.py:74][INFO][Accessing /bootstrap.min.css.map with showBin matched nothing.]
[2019-02-27 19:04:44,476][Thread-5:255736][task_id:django.request][log.py:228][ERROR][Internal Server Error: /bin/bootstrap.min.css.map]
Traceback (most recent call last):
  File "D:\Project\Website\venv\lib\site-packages\django\core\handlers\exception.py", line 34, in inner
    response = get_response(request)
  File "D:\Project\Website\venv\lib\site-packages\django\core\handlers\base.py", line 137, in _get_response
    "returned None instead." % (callback.__module__, view_name)
ValueError: The view staticApp.views.showBin didn't return an HttpResponse object. It returned None instead.
[2019-02-27 19:04:53,616][Thread-1:253460][task_id:root][views.py:74][INFO][Accessing /bootstrap.min.css.map with showBin matched nothing.]
[2019-02-27 19:04:53,694][Thread-1:253460][task_id:django.request][log.py:228][ERROR][Internal Server Error: /bin/bootstrap.min.css.map]
Traceback (most recent call last):
  File "D:\Project\Website\venv\lib\site-packages\django\core\handlers\exception.py", line 34, in inner
    response = get_response(request)
  File "D:\Project\Website\venv\lib\site-packages\django\core\handlers\base.py", line 137, in _get_response
    "returned None instead." % (callback.__module__, view_name)
ValueError: The view staticApp.views.showBin didn't return an HttpResponse object. It returned None instead.
[2019-02-27 19:09:26,019][Thread-14:242232][task_id:django.request][log.py:228][WARNING][Not Found: /robots.txt]
[2019-02-27 19:09:28,133][Thread-15:258584][task_id:django.request][log.py:228][WARNING][Not Found: /favicon.ico]
[2019-02-27 20:21:08,118][Thread-29:262276][task_id:django.request][log.py:228][WARNING][Not Found: /favicon.ico]
[2019-02-27 21:47:01,220][Thread-42:268556][task_id:django.request][log.py:228][WARNING][Not Found: /favicon.ico]
[2019-02-27 21:47:50,848][Thread-43:268824][task_id:django.request][log.py:228][WARNING][Not Found: /favicon.ico]
[2019-03-01 18:42:37,224][Thread-1:19476][task_id:root][views.py:14][INFO][Accessing Page / with showMainPage]
[2019-03-01 18:42:37,250][Thread-1:19476][task_id:staticApp.views][views.py:14][INFO][Accessing Page index.html with showMainPage]
[2019-03-01 18:42:39,169][Thread-1:19476][task_id:django.request][log.py:228][WARNING][Not Found: /favicon.ico]
[2019-03-01 18:44:23,299][Thread-6:19568][task_id:staticApp.views][views.py:14][INFO][Accessing Page index.html with showMainPage]
[2019-03-06 16:09:39,980][Thread-1:238396][task_id:root][views.py:14][INFO][Accessing Page / with showMainPage]
[2019-03-06 16:09:40,269][Thread-1:238396][task_id:django.request][log.py:228][WARNING][Not Found: /favicon.ico]
[2019-03-06 16:09:47,624][Thread-1:238396][task_id:root][views.py:12][INFO][Accessing Page home/ with showHome]
[2019-03-06 16:09:47,866][Thread-5:238408][task_id:django.request][log.py:228][WARNING][Not Found: /wp-content/themes/homesite17/fonts/Stanford.ttf]
[2019-03-06 16:09:47,869][Thread-1:238396][task_id:django.request][log.py:228][WARNING][Not Found: /fonts/fontawesome-webfont.woff2]
[2019-03-06 16:09:48,097][Thread-1:238396][task_id:django.request][log.py:228][WARNING][Not Found: /wp-content/themes/homesite17/fonts/Stanford.woff]
[2019-03-06 16:09:48,101][Thread-5:238408][task_id:django.request][log.py:228][WARNING][Not Found: /fonts/fontawesome-webfont.woff]
[2019-03-06 16:09:48,240][Thread-5:238408][task_id:django.request][log.py:228][WARNING][Not Found: /fonts/fontawesome-webfont.ttf]
[2019-03-08 18:33:50,089][Thread-1:279588][task_id:django.request][log.py:228][ERROR][Internal Server Error: /captcha/index]
Traceback (most recent call last):
  File "D:\Project\Website\venv\lib\site-packages\django\core\handlers\exception.py", line 34, in inner
    response = get_response(request)
  File "D:\Project\Website\venv\lib\site-packages\django\core\handlers\base.py", line 126, in _get_response
    response = self.process_exception_by_middleware(e, request)
  File "D:\Project\Website\venv\lib\site-packages\django\core\handlers\base.py", line 124, in _get_response
    response = wrapped_callback(request, *callback_args, **callback_kwargs)
  File "D:\Project\Website\captchaApp\views.py", line 37, in showIndex
    for hero in heroes:
  File "D:\Project\Website\venv\lib\site-packages\django\db\models\query.py", line 268, in __iter__
    self._fetch_all()
  File "D:\Project\Website\venv\lib\site-packages\django\db\models\query.py", line 1186, in _fetch_all
    self._result_cache = list(self._iterable_class(self))
  File "D:\Project\Website\venv\lib\site-packages\django\db\models\query.py", line 106, in __iter__
    for row in compiler.results_iter(chunked_fetch=self.chunked_fetch, chunk_size=self.chunk_size):
  File "D:\Project\Website\venv\lib\site-packages\django\db\models\sql\compiler.py", line 1017, in results_iter
    results = self.execute_sql(MULTI, chunked_fetch=chunked_fetch, chunk_size=chunk_size)
  File "D:\Project\Website\venv\lib\site-packages\django\db\models\sql\compiler.py", line 1052, in execute_sql
    sql, params = self.as_sql()
  File "D:\Project\Website\venv\lib\site-packages\django\db\models\sql\compiler.py", line 472, in as_sql
    distinct_params,
  File "D:\Project\Website\venv\lib\site-packages\django\db\backends\base\operations.py", line 171, in distinct_sql
    raise NotSupportedError('DISTINCT ON fields is not supported by this database backend')
django.db.utils.NotSupportedError: DISTINCT ON fields is not supported by this database backend
[2019-03-08 18:33:50,353][Thread-1:279588][task_id:django.request][log.py:228][WARNING][Not Found: /favicon.ico]
[2019-03-08 18:34:06,909][Thread-1:281888][task_id:django.request][log.py:228][ERROR][Internal Server Error: /captcha/index]
Traceback (most recent call last):
  File "D:\Project\Website\venv\lib\site-packages\django\core\handlers\exception.py", line 34, in inner
    response = get_response(request)
  File "D:\Project\Website\venv\lib\site-packages\django\core\handlers\base.py", line 126, in _get_response
    response = self.process_exception_by_middleware(e, request)
  File "D:\Project\Website\venv\lib\site-packages\django\core\handlers\base.py", line 124, in _get_response
    response = wrapped_callback(request, *callback_args, **callback_kwargs)
  File "D:\Project\Website\captchaApp\views.py", line 37, in showIndex
    for hero in heroes:
  File "D:\Project\Website\venv\lib\site-packages\django\db\models\query.py", line 268, in __iter__
    self._fetch_all()
  File "D:\Project\Website\venv\lib\site-packages\django\db\models\query.py", line 1186, in _fetch_all
    self._result_cache = list(self._iterable_class(self))
  File "D:\Project\Website\venv\lib\site-packages\django\db\models\query.py", line 106, in __iter__
    for row in compiler.results_iter(chunked_fetch=self.chunked_fetch, chunk_size=self.chunk_size):
  File "D:\Project\Website\venv\lib\site-packages\django\db\models\sql\compiler.py", line 1017, in results_iter
    results = self.execute_sql(MULTI, chunked_fetch=chunked_fetch, chunk_size=chunk_size)
  File "D:\Project\Website\venv\lib\site-packages\django\db\models\sql\compiler.py", line 1052, in execute_sql
    sql, params = self.as_sql()
  File "D:\Project\Website\venv\lib\site-packages\django\db\models\sql\compiler.py", line 472, in as_sql
    distinct_params,
  File "D:\Project\Website\venv\lib\site-packages\django\db\backends\base\operations.py", line 171, in distinct_sql
    raise NotSupportedError('DISTINCT ON fields is not supported by this database backend')
django.db.utils.NotSupportedError: DISTINCT ON fields is not supported by this database backend
[2019-03-08 18:34:13,148][Thread-1:281888][task_id:django.request][log.py:228][ERROR][Internal Server Error: /captcha/index]
Traceback (most recent call last):
  File "D:\Project\Website\venv\lib\site-packages\django\core\handlers\exception.py", line 34, in inner
    response = get_response(request)
  File "D:\Project\Website\venv\lib\site-packages\django\core\handlers\base.py", line 126, in _get_response
    response = self.process_exception_by_middleware(e, request)
  File "D:\Project\Website\venv\lib\site-packages\django\core\handlers\base.py", line 124, in _get_response
    response = wrapped_callback(request, *callback_args, **callback_kwargs)
  File "D:\Project\Website\captchaApp\views.py", line 37, in showIndex
    for hero in heroes:
  File "D:\Project\Website\venv\lib\site-packages\django\db\models\query.py", line 268, in __iter__
    self._fetch_all()
  File "D:\Project\Website\venv\lib\site-packages\django\db\models\query.py", line 1186, in _fetch_all
    self._result_cache = list(self._iterable_class(self))
  File "D:\Project\Website\venv\lib\site-packages\django\db\models\query.py", line 106, in __iter__
    for row in compiler.results_iter(chunked_fetch=self.chunked_fetch, chunk_size=self.chunk_size):
  File "D:\Project\Website\venv\lib\site-packages\django\db\models\sql\compiler.py", line 1017, in results_iter
    results = self.execute_sql(MULTI, chunked_fetch=chunked_fetch, chunk_size=chunk_size)
  File "D:\Project\Website\venv\lib\site-packages\django\db\models\sql\compiler.py", line 1052, in execute_sql
    sql, params = self.as_sql()
  File "D:\Project\Website\venv\lib\site-packages\django\db\models\sql\compiler.py", line 472, in as_sql
    distinct_params,
  File "D:\Project\Website\venv\lib\site-packages\django\db\backends\base\operations.py", line 171, in distinct_sql
    raise NotSupportedError('DISTINCT ON fields is not supported by this database backend')
django.db.utils.NotSupportedError: DISTINCT ON fields is not supported by this database backend
[2019-03-08 18:36:40,796][Thread-1:282212][task_id:django.request][log.py:228][ERROR][Internal Server Error: /captcha/index]
Traceback (most recent call last):
  File "D:\Project\Website\venv\lib\site-packages\django\core\handlers\exception.py", line 34, in inner
    response = get_response(request)
  File "D:\Project\Website\venv\lib\site-packages\django\core\handlers\base.py", line 126, in _get_response
    response = self.process_exception_by_middleware(e, request)
  File "D:\Project\Website\venv\lib\site-packages\django\core\handlers\base.py", line 124, in _get_response
    response = wrapped_callback(request, *callback_args, **callback_kwargs)
  File "D:\Project\Website\captchaApp\views.py", line 39, in showIndex
    'user': hero.user,
AttributeError: 'dict' object has no attribute 'user'
[2019-03-08 18:41:59,462][Thread-1:281624][task_id:django.request][log.py:228][ERROR][Internal Server Error: /captcha/index]
Traceback (most recent call last):
  File "D:\Project\Website\venv\lib\site-packages\django\core\handlers\exception.py", line 34, in inner
    response = get_response(request)
  File "D:\Project\Website\venv\lib\site-packages\django\core\handlers\base.py", line 126, in _get_response
    response = self.process_exception_by_middleware(e, request)
  File "D:\Project\Website\venv\lib\site-packages\django\core\handlers\base.py", line 124, in _get_response
    response = wrapped_callback(request, *callback_args, **callback_kwargs)
  File "D:\Project\Website\captchaApp\views.py", line 39, in showIndex
    'user': hero.user,
AttributeError: 'dict' object has no attribute 'user'
[2019-03-08 18:42:10,771][Thread-1:281624][task_id:django.request][log.py:228][ERROR][Internal Server Error: /captcha/index]
Traceback (most recent call last):
  File "D:\Project\Website\venv\lib\site-packages\django\core\handlers\exception.py", line 34, in inner
    response = get_response(request)
  File "D:\Project\Website\venv\lib\site-packages\django\core\handlers\base.py", line 126, in _get_response
    response = self.process_exception_by_middleware(e, request)
  File "D:\Project\Website\venv\lib\site-packages\django\core\handlers\base.py", line 124, in _get_response
    response = wrapped_callback(request, *callback_args, **callback_kwargs)
  File "D:\Project\Website\captchaApp\views.py", line 39, in showIndex
    'user': hero.user,
AttributeError: 'dict' object has no attribute 'user'
[2019-03-08 19:08:29,600][Thread-6:271760][task_id:root][views.py:74][INFO][Accessing /bootstrap.min.css.map with showBin matched nothing.]
[2019-03-08 19:08:29,604][Thread-6:271760][task_id:django.request][log.py:228][ERROR][Internal Server Error: /bin/bootstrap.min.css.map]
Traceback (most recent call last):
  File "D:\Project\Website\venv\lib\site-packages\django\core\handlers\exception.py", line 34, in inner
    response = get_response(request)
  File "D:\Project\Website\venv\lib\site-packages\django\core\handlers\base.py", line 137, in _get_response
    "returned None instead." % (callback.__module__, view_name)
ValueError: The view staticApp.views.showBin didn't return an HttpResponse object. It returned None instead.
[2019-03-08 19:15:33,593][Thread-3:269292][task_id:root][views.py:74][INFO][Accessing /bootstrap.min.css.map with showBin matched nothing.]
[2019-03-08 19:15:33,597][Thread-3:269292][task_id:django.request][log.py:228][ERROR][Internal Server Error: /bin/bootstrap.min.css.map]
Traceback (most recent call last):
  File "D:\Project\Website\venv\lib\site-packages\django\core\handlers\exception.py", line 34, in inner
    response = get_response(request)
  File "D:\Project\Website\venv\lib\site-packages\django\core\handlers\base.py", line 137, in _get_response
    "returned None instead." % (callback.__module__, view_name)
ValueError: The view staticApp.views.showBin didn't return an HttpResponse object. It returned None instead.
[2019-03-08 19:16:09,731][Thread-3:269292][task_id:root][views.py:74][INFO][Accessing /bootstrap.min.css.map with showBin matched nothing.]
[2019-03-08 19:16:09,732][Thread-3:269292][task_id:django.request][log.py:228][ERROR][Internal Server Error: /bin/bootstrap.min.css.map]
Traceback (most recent call last):
  File "D:\Project\Website\venv\lib\site-packages\django\core\handlers\exception.py", line 34, in inner
    response = get_response(request)
  File "D:\Project\Website\venv\lib\site-packages\django\core\handlers\base.py", line 137, in _get_response
    "returned None instead." % (callback.__module__, view_name)
ValueError: The view staticApp.views.showBin didn't return an HttpResponse object. It returned None instead.
[2019-03-08 19:16:35,091][Thread-3:269292][task_id:root][views.py:74][INFO][Accessing /bootstrap.min.css.map with showBin matched nothing.]
[2019-03-08 19:16:35,092][Thread-3:269292][task_id:django.request][log.py:228][ERROR][Internal Server Error: /bin/bootstrap.min.css.map]
Traceback (most recent call last):
  File "D:\Project\Website\venv\lib\site-packages\django\core\handlers\exception.py", line 34, in inner
    response = get_response(request)
  File "D:\Project\Website\venv\lib\site-packages\django\core\handlers\base.py", line 137, in _get_response
    "returned None instead." % (callback.__module__, view_name)
ValueError: The view staticApp.views.showBin didn't return an HttpResponse object. It returned None instead.
[2019-03-08 19:26:24,427][Thread-1:284648][task_id:root][views.py:74][INFO][Accessing /bootstrap.min.css.map with showBin matched nothing.]
[2019-03-08 19:26:24,432][Thread-1:284648][task_id:django.request][log.py:228][ERROR][Internal Server Error: /bin/bootstrap.min.css.map]
Traceback (most recent call last):
  File "D:\Project\Website\venv\lib\site-packages\django\core\handlers\exception.py", line 34, in inner
    response = get_response(request)
  File "D:\Project\Website\venv\lib\site-packages\django\core\handlers\base.py", line 137, in _get_response
    "returned None instead." % (callback.__module__, view_name)
ValueError: The view staticApp.views.showBin didn't return an HttpResponse object. It returned None instead.
[2019-03-08 19:27:53,065][Thread-3:284276][task_id:root][views.py:74][INFO][Accessing /bootstrap.min.css.map with showBin matched nothing.]
[2019-03-08 19:27:53,071][Thread-3:284276][task_id:django.request][log.py:228][ERROR][Internal Server Error: /bin/bootstrap.min.css.map]
Traceback (most recent call last):
  File "D:\Project\Website\venv\lib\site-packages\django\core\handlers\exception.py", line 34, in inner
    response = get_response(request)
  File "D:\Project\Website\venv\lib\site-packages\django\core\handlers\base.py", line 137, in _get_response
    "returned None instead." % (callback.__module__, view_name)
ValueError: The view staticApp.views.showBin didn't return an HttpResponse object. It returned None instead.
[2019-03-08 19:27:57,757][Thread-1:283992][task_id:root][views.py:74][INFO][Accessing /bootstrap.min.css.map with showBin matched nothing.]
[2019-03-08 19:27:57,757][Thread-1:283992][task_id:django.request][log.py:228][ERROR][Internal Server Error: /bin/bootstrap.min.css.map]
Traceback (most recent call last):
  File "D:\Project\Website\venv\lib\site-packages\django\core\handlers\exception.py", line 34, in inner
    response = get_response(request)
  File "D:\Project\Website\venv\lib\site-packages\django\core\handlers\base.py", line 137, in _get_response
    "returned None instead." % (callback.__module__, view_name)
ValueError: The view staticApp.views.showBin didn't return an HttpResponse object. It returned None instead.
[2019-03-08 20:20:47,081][Thread-3:287108][task_id:django.request][log.py:228][ERROR][Internal Server Error: /captcha/upload]
Traceback (most recent call last):
  File "D:\Project\Website\venv\lib\site-packages\django\core\handlers\exception.py", line 34, in inner
    response = get_response(request)
  File "D:\Project\Website\venv\lib\site-packages\django\core\handlers\base.py", line 126, in _get_response
    response = self.process_exception_by_middleware(e, request)
  File "D:\Project\Website\venv\lib\site-packages\django\core\handlers\base.py", line 124, in _get_response
    response = wrapped_callback(request, *callback_args, **callback_kwargs)
  File "D:\Project\Website\captchaApp\views.py", line 131, in upload
    file_name = ans+'_'+str(random.randint(1000,9999))+'_'+pic[-4:]
TypeError: 'InMemoryUploadedFile' object is not subscriptable
[2019-03-08 20:20:51,872][Thread-3:287108][task_id:root][views.py:74][INFO][Accessing /bootstrap.min.css.map with showBin matched nothing.]
[2019-03-08 20:20:51,873][Thread-3:287108][task_id:django.request][log.py:228][ERROR][Internal Server Error: /bin/bootstrap.min.css.map]
Traceback (most recent call last):
  File "D:\Project\Website\venv\lib\site-packages\django\core\handlers\exception.py", line 34, in inner
    response = get_response(request)
  File "D:\Project\Website\venv\lib\site-packages\django\core\handlers\base.py", line 137, in _get_response
    "returned None instead." % (callback.__module__, view_name)
ValueError: The view staticApp.views.showBin didn't return an HttpResponse object. It returned None instead.
[2019-03-08 20:21:35,849][Thread-1:277744][task_id:root][views.py:74][INFO][Accessing /bootstrap.min.css.map with showBin matched nothing.]
[2019-03-08 20:21:35,855][Thread-1:277744][task_id:django.request][log.py:228][ERROR][Internal Server Error: /bin/bootstrap.min.css.map]
Traceback (most recent call last):
  File "D:\Project\Website\venv\lib\site-packages\django\core\handlers\exception.py", line 34, in inner
    response = get_response(request)
  File "D:\Project\Website\venv\lib\site-packages\django\core\handlers\base.py", line 137, in _get_response
    "returned None instead." % (callback.__module__, view_name)
ValueError: The view staticApp.views.showBin didn't return an HttpResponse object. It returned None instead.
[2019-03-08 20:21:42,781][Thread-1:277744][task_id:captchaApp.views][views.py:132][ERROR][123_6340_123]
[2019-03-08 20:21:42,782][Thread-1:277744][task_id:django.request][log.py:228][ERROR][Internal Server Error: /captcha/upload]
Traceback (most recent call last):
  File "D:\Project\Website\venv\lib\site-packages\django\core\handlers\exception.py", line 34, in inner
    response = get_response(request)
  File "D:\Project\Website\venv\lib\site-packages\django\core\handlers\base.py", line 126, in _get_response
    response = self.process_exception_by_middleware(e, request)
  File "D:\Project\Website\venv\lib\site-packages\django\core\handlers\base.py", line 124, in _get_response
    response = wrapped_callback(request, *callback_args, **callback_kwargs)
  File "D:\Project\Website\captchaApp\views.py", line 134, in upload
    f.write(pic)
TypeError: a bytes-like object is required, not 'InMemoryUploadedFile'
[2019-03-08 20:23:26,021][Thread-3:286916][task_id:root][views.py:74][INFO][Accessing /bootstrap.min.css.map with showBin matched nothing.]
[2019-03-08 20:23:26,026][Thread-3:286916][task_id:django.request][log.py:228][ERROR][Internal Server Error: /bin/bootstrap.min.css.map]
Traceback (most recent call last):
  File "D:\Project\Website\venv\lib\site-packages\django\core\handlers\exception.py", line 34, in inner
    response = get_response(request)
  File "D:\Project\Website\venv\lib\site-packages\django\core\handlers\base.py", line 137, in _get_response
    "returned None instead." % (callback.__module__, view_name)
ValueError: The view staticApp.views.showBin didn't return an HttpResponse object. It returned None instead.
[2019-03-08 20:23:52,920][Thread-3:277232][task_id:root][views.py:74][INFO][Accessing /bootstrap.min.css.map with showBin matched nothing.]
[2019-03-08 20:23:52,925][Thread-3:277232][task_id:django.request][log.py:228][ERROR][Internal Server Error: /bin/bootstrap.min.css.map]
Traceback (most recent call last):
  File "D:\Project\Website\venv\lib\site-packages\django\core\handlers\exception.py", line 34, in inner
    response = get_response(request)
  File "D:\Project\Website\venv\lib\site-packages\django\core\handlers\base.py", line 137, in _get_response
    "returned None instead." % (callback.__module__, view_name)
ValueError: The view staticApp.views.showBin didn't return an HttpResponse object. It returned None instead.
[2019-03-08 20:23:59,773][Thread-3:277232][task_id:captchaApp.views][views.py:132][INFO][123_5468_123]
[2019-03-08 20:25:47,819][Thread-3:281972][task_id:root][views.py:74][INFO][Accessing /bootstrap.min.css.map with showBin matched nothing.]
[2019-03-08 20:25:47,824][Thread-3:281972][task_id:django.request][log.py:228][ERROR][Internal Server Error: /bin/bootstrap.min.css.map]
Traceback (most recent call last):
  File "D:\Project\Website\venv\lib\site-packages\django\core\handlers\exception.py", line 34, in inner
    response = get_response(request)
  File "D:\Project\Website\venv\lib\site-packages\django\core\handlers\base.py", line 137, in _get_response
    "returned None instead." % (callback.__module__, view_name)
ValueError: The view staticApp.views.showBin didn't return an HttpResponse object. It returned None instead.
[2019-03-08 20:25:52,744][Thread-3:281972][task_id:captchaApp.views][views.py:132][INFO][./captcha/123_1980_.jpg]
[2019-03-08 20:25:57,585][Thread-4:287108][task_id:root][views.py:74][INFO][Accessing /bootstrap.min.css.map with showBin matched nothing.]
[2019-03-08 20:25:57,585][Thread-4:287108][task_id:django.request][log.py:228][ERROR][Internal Server Error: /bin/bootstrap.min.css.map]
Traceback (most recent call last):
  File "D:\Project\Website\venv\lib\site-packages\django\core\handlers\exception.py", line 34, in inner
    response = get_response(request)
  File "D:\Project\Website\venv\lib\site-packages\django\core\handlers\base.py", line 137, in _get_response
    "returned None instead." % (callback.__module__, view_name)
ValueError: The view staticApp.views.showBin didn't return an HttpResponse object. It returned None instead.
[2019-03-08 20:26:39,459][Thread-7:214632][task_id:root][views.py:74][INFO][Accessing /bootstrap.min.css.map with showBin matched nothing.]
[2019-03-08 20:26:39,460][Thread-7:214632][task_id:django.request][log.py:228][ERROR][Internal Server Error: /bin/bootstrap.min.css.map]
Traceback (most recent call last):
  File "D:\Project\Website\venv\lib\site-packages\django\core\handlers\exception.py", line 34, in inner
    response = get_response(request)
  File "D:\Project\Website\venv\lib\site-packages\django\core\handlers\base.py", line 137, in _get_response
    "returned None instead." % (callback.__module__, view_name)
ValueError: The view staticApp.views.showBin didn't return an HttpResponse object. It returned None instead.
[2019-03-10 10:02:18,939][Thread-7:328044][task_id:root][views.py:15][INFO][Accessing Page / with showMainPage]
[2019-03-10 10:02:19,302][Thread-7:328044][task_id:django.request][log.py:228][WARNING][Not Found: /favicon.ico]
[2019-03-10 10:02:21,553][Thread-7:328044][task_id:staticApp.views][views.py:14][INFO][Accessing Page index.html with showMainPage]
[2019-03-10 10:02:26,655][Thread-8:292300][task_id:root][views.py:12][INFO][Accessing Page home/ with showHome]
[2019-03-10 10:02:26,958][Thread-9:353016][task_id:django.request][log.py:228][WARNING][Not Found: /wp-content/themes/homesite17/fonts/Stanford.ttf]
[2019-03-10 10:02:26,974][Thread-12:307480][task_id:root][views.py:74][INFO][Accessing /fonts/weathericons-regular-webfont.woff2 with showBin matched nothing.]
[2019-03-10 10:02:26,982][Thread-12:307480][task_id:django.request][log.py:228][ERROR][Internal Server Error: /bin/fonts/weathericons-regular-webfont.woff2]
Traceback (most recent call last):
  File "D:\Project\Website\venv\lib\site-packages\django\core\handlers\exception.py", line 34, in inner
    response = get_response(request)
  File "D:\Project\Website\venv\lib\site-packages\django\core\handlers\base.py", line 137, in _get_response
    "returned None instead." % (callback.__module__, view_name)
ValueError: The view staticApp.views.showBin didn't return an HttpResponse object. It returned None instead.
[2019-03-10 10:02:27,234][Thread-12:307480][task_id:django.request][log.py:228][WARNING][Not Found: /wp-content/themes/homesite17/fonts/Stanford.woff]
[2019-03-10 10:02:27,237][Thread-9:353016][task_id:root][views.py:74][INFO][Accessing /fonts/weathericons-regular-webfont.woff with showBin matched nothing.]
[2019-03-10 10:02:27,242][Thread-9:353016][task_id:django.request][log.py:228][ERROR][Internal Server Error: /bin/fonts/weathericons-regular-webfont.woff]
Traceback (most recent call last):
  File "D:\Project\Website\venv\lib\site-packages\django\core\handlers\exception.py", line 34, in inner
    response = get_response(request)
  File "D:\Project\Website\venv\lib\site-packages\django\core\handlers\base.py", line 137, in _get_response
    "returned None instead." % (callback.__module__, view_name)
ValueError: The view staticApp.views.showBin didn't return an HttpResponse object. It returned None instead.
[2019-03-10 10:02:27,412][Thread-9:353016][task_id:root][views.py:74][INFO][Accessing /fonts/weathericons-regular-webfont.ttf with showBin matched nothing.]
[2019-03-10 10:02:27,413][Thread-9:353016][task_id:django.request][log.py:228][ERROR][Internal Server Error: /bin/fonts/weathericons-regular-webfont.ttf]
Traceback (most recent call last):
  File "D:\Project\Website\venv\lib\site-packages\django\core\handlers\exception.py", line 34, in inner
    response = get_response(request)
  File "D:\Project\Website\venv\lib\site-packages\django\core\handlers\base.py", line 137, in _get_response
    "returned None instead." % (callback.__module__, view_name)
ValueError: The view staticApp.views.showBin didn't return an HttpResponse object. It returned None instead.
[2019-03-10 10:12:22,192][Thread-1:344380][task_id:root][views.py:15][INFO][Accessing Page / with showMainPage]
[2019-03-10 10:12:23,417][Thread-1:344380][task_id:staticApp.views][views.py:14][INFO][Accessing Page index.html with showMainPage]
[2019-03-10 10:12:25,600][Thread-3:353612][task_id:root][views.py:12][INFO][Accessing Page home/ with showHome]
[2019-03-10 10:12:25,880][Thread-4:352308][task_id:django.request][log.py:228][WARNING][Not Found: /wp-content/themes/homesite17/fonts/Stanford.ttf]
[2019-03-10 10:12:25,881][Thread-6:284928][task_id:root][views.py:74][INFO][Accessing /fonts/weathericons-regular-webfont.woff2 with showBin matched nothing.]
[2019-03-10 10:12:25,880][Thread-5:291672][task_id:django.request][log.py:228][ERROR][Internal Server Error: /fonts/fontawesome-webfont.woff2]
Traceback (most recent call last):
  File "D:\Project\Website\venv\lib\site-packages\django\core\handlers\exception.py", line 34, in inner
    response = get_response(request)
  File "D:\Project\Website\venv\lib\site-packages\django\core\handlers\base.py", line 126, in _get_response
    response = self.process_exception_by_middleware(e, request)
  File "D:\Project\Website\venv\lib\site-packages\django\core\handlers\base.py", line 124, in _get_response
    response = wrapped_callback(request, *callback_args, **callback_kwargs)
  File "D:\Project\Website\staticApp\views.py", line 88, in showFont
    with open('./bin/' + path, encoding='UTF-8') as f:
FileNotFoundError: [Errno 2] No such file or directory: './bin/fontawesome-webfont.woff2'
[2019-03-10 10:12:25,888][Thread-6:284928][task_id:django.request][log.py:228][ERROR][Internal Server Error: /bin/fonts/weathericons-regular-webfont.woff2]
Traceback (most recent call last):
  File "D:\Project\Website\venv\lib\site-packages\django\core\handlers\exception.py", line 34, in inner
    response = get_response(request)
  File "D:\Project\Website\venv\lib\site-packages\django\core\handlers\base.py", line 137, in _get_response
    "returned None instead." % (callback.__module__, view_name)
ValueError: The view staticApp.views.showBin didn't return an HttpResponse object. It returned None instead.
[2019-03-10 10:12:26,110][Thread-6:284928][task_id:django.request][log.py:228][WARNING][Not Found: /wp-content/themes/homesite17/fonts/Stanford.woff]
[2019-03-10 10:12:26,112][Thread-4:352308][task_id:root][views.py:74][INFO][Accessing /fonts/weathericons-regular-webfont.woff with showBin matched nothing.]
[2019-03-10 10:12:26,113][Thread-5:291672][task_id:django.request][log.py:228][ERROR][Internal Server Error: /fonts/fontawesome-webfont.woff]
Traceback (most recent call last):
  File "D:\Project\Website\venv\lib\site-packages\django\core\handlers\exception.py", line 34, in inner
    response = get_response(request)
  File "D:\Project\Website\venv\lib\site-packages\django\core\handlers\base.py", line 126, in _get_response
    response = self.process_exception_by_middleware(e, request)
  File "D:\Project\Website\venv\lib\site-packages\django\core\handlers\base.py", line 124, in _get_response
    response = wrapped_callback(request, *callback_args, **callback_kwargs)
  File "D:\Project\Website\staticApp\views.py", line 88, in showFont
    with open('./bin/' + path, encoding='UTF-8') as f:
FileNotFoundError: [Errno 2] No such file or directory: './bin/fontawesome-webfont.woff'
[2019-03-10 10:12:26,114][Thread-4:352308][task_id:django.request][log.py:228][ERROR][Internal Server Error: /bin/fonts/weathericons-regular-webfont.woff]
Traceback (most recent call last):
  File "D:\Project\Website\venv\lib\site-packages\django\core\handlers\exception.py", line 34, in inner
    response = get_response(request)
  File "D:\Project\Website\venv\lib\site-packages\django\core\handlers\base.py", line 137, in _get_response
    "returned None instead." % (callback.__module__, view_name)
ValueError: The view staticApp.views.showBin didn't return an HttpResponse object. It returned None instead.
[2019-03-10 10:12:26,264][Thread-5:291672][task_id:root][views.py:74][INFO][Accessing /fonts/weathericons-regular-webfont.ttf with showBin matched nothing.]
[2019-03-10 10:12:26,264][Thread-4:352308][task_id:django.request][log.py:228][ERROR][Internal Server Error: /fonts/fontawesome-webfont.ttf]
Traceback (most recent call last):
  File "D:\Project\Website\venv\lib\site-packages\django\core\handlers\exception.py", line 34, in inner
    response = get_response(request)
  File "D:\Project\Website\venv\lib\site-packages\django\core\handlers\base.py", line 126, in _get_response
    response = self.process_exception_by_middleware(e, request)
  File "D:\Project\Website\venv\lib\site-packages\django\core\handlers\base.py", line 124, in _get_response
    response = wrapped_callback(request, *callback_args, **callback_kwargs)
  File "D:\Project\Website\staticApp\views.py", line 88, in showFont
    with open('./bin/' + path, encoding='UTF-8') as f:
FileNotFoundError: [Errno 2] No such file or directory: './bin/fontawesome-webfont.ttf'
[2019-03-10 10:12:26,265][Thread-5:291672][task_id:django.request][log.py:228][ERROR][Internal Server Error: /bin/fonts/weathericons-regular-webfont.ttf]
Traceback (most recent call last):
  File "D:\Project\Website\venv\lib\site-packages\django\core\handlers\exception.py", line 34, in inner
    response = get_response(request)
  File "D:\Project\Website\venv\lib\site-packages\django\core\handlers\base.py", line 137, in _get_response
    "returned None instead." % (callback.__module__, view_name)
ValueError: The view staticApp.views.showBin didn't return an HttpResponse object. It returned None instead.
[2019-03-10 10:12:29,050][Thread-6:284928][task_id:root][views.py:74][INFO][Accessing /master.min.css.map with showBin matched nothing.]
[2019-03-10 10:12:29,050][Thread-6:284928][task_id:django.request][log.py:228][ERROR][Internal Server Error: /bin/master.min.css.map]
Traceback (most recent call last):
  File "D:\Project\Website\venv\lib\site-packages\django\core\handlers\exception.py", line 34, in inner
    response = get_response(request)
  File "D:\Project\Website\venv\lib\site-packages\django\core\handlers\base.py", line 137, in _get_response
    "returned None instead." % (callback.__module__, view_name)
ValueError: The view staticApp.views.showBin didn't return an HttpResponse object. It returned None instead.
[2019-03-10 10:13:33,785][Thread-1:304616][task_id:root][views.py:12][INFO][Accessing Page home/ with showHome]
[2019-03-10 10:13:34,148][Thread-4:352884][task_id:root][views.py:74][INFO][Accessing /fonts/weathericons-regular-webfont.woff2 with showBin matched nothing.]
[2019-03-10 10:13:34,157][Thread-6:352416][task_id:django.request][log.py:228][WARNING][Not Found: /wp-content/themes/homesite17/fonts/Stanford.ttf]
[2019-03-10 10:13:34,155][Thread-3:291748][task_id:django.request][log.py:228][ERROR][Internal Server Error: /fonts/fontawesome-webfont.woff2]
Traceback (most recent call last):
  File "D:\Project\Website\venv\lib\site-packages\django\core\handlers\exception.py", line 34, in inner
    response = get_response(request)
  File "D:\Project\Website\venv\lib\site-packages\django\core\handlers\base.py", line 126, in _get_response
    response = self.process_exception_by_middleware(e, request)
  File "D:\Project\Website\venv\lib\site-packages\django\core\handlers\base.py", line 124, in _get_response
    response = wrapped_callback(request, *callback_args, **callback_kwargs)
  File "D:\Project\Website\staticApp\views.py", line 88, in showFont
    with open('./fonts/' + path, encoding='rb') as f:
LookupError: unknown encoding: rb
[2019-03-10 10:13:34,156][Thread-4:352884][task_id:django.request][log.py:228][ERROR][Internal Server Error: /bin/fonts/weathericons-regular-webfont.woff2]
Traceback (most recent call last):
  File "D:\Project\Website\venv\lib\site-packages\django\core\handlers\exception.py", line 34, in inner
    response = get_response(request)
  File "D:\Project\Website\venv\lib\site-packages\django\core\handlers\base.py", line 137, in _get_response
    "returned None instead." % (callback.__module__, view_name)
ValueError: The view staticApp.views.showBin didn't return an HttpResponse object. It returned None instead.
[2019-03-10 10:13:34,262][Thread-4:352884][task_id:root][views.py:74][INFO][Accessing /master.min.css.map with showBin matched nothing.]
[2019-03-10 10:13:34,290][Thread-3:291748][task_id:django.request][log.py:228][WARNING][Not Found: /wp-content/themes/homesite17/fonts/Stanford.woff]
[2019-03-10 10:13:34,262][Thread-4:352884][task_id:django.request][log.py:228][ERROR][Internal Server Error: /bin/master.min.css.map]
Traceback (most recent call last):
  File "D:\Project\Website\venv\lib\site-packages\django\core\handlers\exception.py", line 34, in inner
    response = get_response(request)
  File "D:\Project\Website\venv\lib\site-packages\django\core\handlers\base.py", line 137, in _get_response
    "returned None instead." % (callback.__module__, view_name)
ValueError: The view staticApp.views.showBin didn't return an HttpResponse object. It returned None instead.
[2019-03-10 10:13:34,355][Thread-3:291748][task_id:root][views.py:74][INFO][Accessing /fonts/weathericons-regular-webfont.woff with showBin matched nothing.]
[2019-03-10 10:13:34,356][Thread-3:291748][task_id:django.request][log.py:228][ERROR][Internal Server Error: /bin/fonts/weathericons-regular-webfont.woff]
Traceback (most recent call last):
  File "D:\Project\Website\venv\lib\site-packages\django\core\handlers\exception.py", line 34, in inner
    response = get_response(request)
  File "D:\Project\Website\venv\lib\site-packages\django\core\handlers\base.py", line 137, in _get_response
    "returned None instead." % (callback.__module__, view_name)
ValueError: The view staticApp.views.showBin didn't return an HttpResponse object. It returned None instead.
[2019-03-10 10:13:34,358][Thread-4:352884][task_id:django.request][log.py:228][ERROR][Internal Server Error: /fonts/fontawesome-webfont.woff]
Traceback (most recent call last):
  File "D:\Project\Website\venv\lib\site-packages\django\core\handlers\exception.py", line 34, in inner
    response = get_response(request)
  File "D:\Project\Website\venv\lib\site-packages\django\core\handlers\base.py", line 126, in _get_response
    response = self.process_exception_by_middleware(e, request)
  File "D:\Project\Website\venv\lib\site-packages\django\core\handlers\base.py", line 124, in _get_response
    response = wrapped_callback(request, *callback_args, **callback_kwargs)
  File "D:\Project\Website\staticApp\views.py", line 88, in showFont
    with open('./fonts/' + path, encoding='rb') as f:
LookupError: unknown encoding: rb
[2019-03-10 10:13:34,717][Thread-4:352884][task_id:root][views.py:74][INFO][Accessing /fonts/weathericons-regular-webfont.ttf with showBin matched nothing.]
[2019-03-10 10:13:34,718][Thread-4:352884][task_id:django.request][log.py:228][ERROR][Internal Server Error: /bin/fonts/weathericons-regular-webfont.ttf]
Traceback (most recent call last):
  File "D:\Project\Website\venv\lib\site-packages\django\core\handlers\exception.py", line 34, in inner
    response = get_response(request)
  File "D:\Project\Website\venv\lib\site-packages\django\core\handlers\base.py", line 137, in _get_response
    "returned None instead." % (callback.__module__, view_name)
ValueError: The view staticApp.views.showBin didn't return an HttpResponse object. It returned None instead.
[2019-03-10 10:13:34,719][Thread-3:291748][task_id:django.request][log.py:228][ERROR][Internal Server Error: /fonts/fontawesome-webfont.ttf]
Traceback (most recent call last):
  File "D:\Project\Website\venv\lib\site-packages\django\core\handlers\exception.py", line 34, in inner
    response = get_response(request)
  File "D:\Project\Website\venv\lib\site-packages\django\core\handlers\base.py", line 126, in _get_response
    response = self.process_exception_by_middleware(e, request)
  File "D:\Project\Website\venv\lib\site-packages\django\core\handlers\base.py", line 124, in _get_response
    response = wrapped_callback(request, *callback_args, **callback_kwargs)
  File "D:\Project\Website\staticApp\views.py", line 88, in showFont
    with open('./fonts/' + path, encoding='rb') as f:
LookupError: unknown encoding: rb
[2019-03-10 10:14:54,660][Thread-1:352920][task_id:root][views.py:12][INFO][Accessing Page home/ with showHome]
[2019-03-10 10:14:54,987][Thread-6:350152][task_id:root][views.py:74][INFO][Accessing /fonts/weathericons-regular-webfont.woff2 with showBin matched nothing.]
[2019-03-10 10:14:54,994][Thread-4:351556][task_id:django.request][log.py:228][WARNING][Not Found: /wp-content/themes/homesite17/fonts/Stanford.ttf]
[2019-03-10 10:14:54,995][Thread-6:350152][task_id:django.request][log.py:228][ERROR][Internal Server Error: /bin/fonts/weathericons-regular-webfont.woff2]
Traceback (most recent call last):
  File "D:\Project\Website\venv\lib\site-packages\django\core\handlers\exception.py", line 34, in inner
    response = get_response(request)
  File "D:\Project\Website\venv\lib\site-packages\django\core\handlers\base.py", line 137, in _get_response
    "returned None instead." % (callback.__module__, view_name)
ValueError: The view staticApp.views.showBin didn't return an HttpResponse object. It returned None instead.
[2019-03-10 10:14:55,098][Thread-6:350152][task_id:root][views.py:74][INFO][Accessing /master.min.css.map with showBin matched nothing.]
[2019-03-10 10:14:55,111][Thread-3:290200][task_id:django.request][log.py:228][WARNING][Not Found: /wp-content/themes/homesite17/fonts/Stanford.woff]
[2019-03-10 10:14:55,099][Thread-6:350152][task_id:django.request][log.py:228][ERROR][Internal Server Error: /bin/master.min.css.map]
Traceback (most recent call last):
  File "D:\Project\Website\venv\lib\site-packages\django\core\handlers\exception.py", line 34, in inner
    response = get_response(request)
  File "D:\Project\Website\venv\lib\site-packages\django\core\handlers\base.py", line 137, in _get_response
    "returned None instead." % (callback.__module__, view_name)
ValueError: The view staticApp.views.showBin didn't return an HttpResponse object. It returned None instead.
[2019-03-10 10:14:55,176][Thread-6:350152][task_id:root][views.py:74][INFO][Accessing /fonts/weathericons-regular-webfont.woff with showBin matched nothing.]
[2019-03-10 10:14:55,176][Thread-6:350152][task_id:django.request][log.py:228][ERROR][Internal Server Error: /bin/fonts/weathericons-regular-webfont.woff]
Traceback (most recent call last):
  File "D:\Project\Website\venv\lib\site-packages\django\core\handlers\exception.py", line 34, in inner
    response = get_response(request)
  File "D:\Project\Website\venv\lib\site-packages\django\core\handlers\base.py", line 137, in _get_response
    "returned None instead." % (callback.__module__, view_name)
ValueError: The view staticApp.views.showBin didn't return an HttpResponse object. It returned None instead.
[2019-03-10 10:14:55,459][Thread-6:350152][task_id:root][views.py:74][INFO][Accessing /fonts/weathericons-regular-webfont.ttf with showBin matched nothing.]
[2019-03-10 10:14:55,459][Thread-6:350152][task_id:django.request][log.py:228][ERROR][Internal Server Error: /bin/fonts/weathericons-regular-webfont.ttf]
Traceback (most recent call last):
  File "D:\Project\Website\venv\lib\site-packages\django\core\handlers\exception.py", line 34, in inner
    response = get_response(request)
  File "D:\Project\Website\venv\lib\site-packages\django\core\handlers\base.py", line 137, in _get_response
    "returned None instead." % (callback.__module__, view_name)
ValueError: The view staticApp.views.showBin didn't return an HttpResponse object. It returned None instead.
[2019-03-10 10:15:44,271][Thread-1:347912][task_id:root][views.py:12][INFO][Accessing Page home/ with showHome]
[2019-03-10 10:15:44,676][Thread-4:317848][task_id:root][views.py:74][INFO][Accessing /fonts/weathericons-regular-webfont.woff2 with showBin matched nothing.]
[2019-03-10 10:15:44,684][Thread-6:283500][task_id:django.request][log.py:228][WARNING][Not Found: /wp-content/themes/homesite17/fonts/Stanford.ttf]
[2019-03-10 10:15:44,684][Thread-4:317848][task_id:django.request][log.py:228][ERROR][Internal Server Error: /bin/fonts/weathericons-regular-webfont.woff2]
Traceback (most recent call last):
  File "D:\Project\Website\venv\lib\site-packages\django\core\handlers\exception.py", line 34, in inner
    response = get_response(request)
  File "D:\Project\Website\venv\lib\site-packages\django\core\handlers\base.py", line 137, in _get_response
    "returned None instead." % (callback.__module__, view_name)
ValueError: The view staticApp.views.showBin didn't return an HttpResponse object. It returned None instead.
[2019-03-10 10:15:44,793][Thread-4:317848][task_id:root][views.py:74][INFO][Accessing /master.min.css.map with showBin matched nothing.]
[2019-03-10 10:15:44,806][Thread-6:283500][task_id:django.request][log.py:228][WARNING][Not Found: /wp-content/themes/homesite17/fonts/Stanford.woff]
[2019-03-10 10:15:44,793][Thread-4:317848][task_id:django.request][log.py:228][ERROR][Internal Server Error: /bin/master.min.css.map]
Traceback (most recent call last):
  File "D:\Project\Website\venv\lib\site-packages\django\core\handlers\exception.py", line 34, in inner
    response = get_response(request)
  File "D:\Project\Website\venv\lib\site-packages\django\core\handlers\base.py", line 137, in _get_response
    "returned None instead." % (callback.__module__, view_name)
ValueError: The view staticApp.views.showBin didn't return an HttpResponse object. It returned None instead.
[2019-03-10 10:15:44,872][Thread-4:317848][task_id:root][views.py:74][INFO][Accessing /fonts/weathericons-regular-webfont.woff with showBin matched nothing.]
[2019-03-10 10:15:44,872][Thread-4:317848][task_id:django.request][log.py:228][ERROR][Internal Server Error: /bin/fonts/weathericons-regular-webfont.woff]
Traceback (most recent call last):
  File "D:\Project\Website\venv\lib\site-packages\django\core\handlers\exception.py", line 34, in inner
    response = get_response(request)
  File "D:\Project\Website\venv\lib\site-packages\django\core\handlers\base.py", line 137, in _get_response
    "returned None instead." % (callback.__module__, view_name)
ValueError: The view staticApp.views.showBin didn't return an HttpResponse object. It returned None instead.
[2019-03-10 10:15:45,190][Thread-4:317848][task_id:root][views.py:74][INFO][Accessing /fonts/weathericons-regular-webfont.ttf with showBin matched nothing.]
[2019-03-10 10:15:45,190][Thread-4:317848][task_id:django.request][log.py:228][ERROR][Internal Server Error: /bin/fonts/weathericons-regular-webfont.ttf]
Traceback (most recent call last):
  File "D:\Project\Website\venv\lib\site-packages\django\core\handlers\exception.py", line 34, in inner
    response = get_response(request)
  File "D:\Project\Website\venv\lib\site-packages\django\core\handlers\base.py", line 137, in _get_response
    "returned None instead." % (callback.__module__, view_name)
ValueError: The view staticApp.views.showBin didn't return an HttpResponse object. It returned None instead.
[2019-03-10 10:20:33,424][Thread-4:317848][task_id:root][views.py:12][INFO][Accessing Page home/ with showHome]
[2019-03-10 10:20:33,761][Thread-1:347912][task_id:django.request][log.py:228][WARNING][Not Found: /wp-content/themes/homesite17/fonts/Stanford.ttf]
[2019-03-10 10:20:33,763][Thread-5:302212][task_id:root][views.py:74][INFO][Accessing /fonts/weathericons-regular-webfont.woff2 with showBin matched nothing.]
[2019-03-10 10:20:33,764][Thread-6:283500][task_id:django.request][log.py:228][ERROR][Internal Server Error: /fonts/fontawesome-webfont.woff2]
Traceback (most recent call last):
  File "D:\Project\Website\venv\lib\site-packages\django\core\handlers\exception.py", line 34, in inner
    response = get_response(request)
  File "D:\Project\Website\venv\lib\site-packages\django\core\handlers\base.py", line 126, in _get_response
    response = self.process_exception_by_middleware(e, request)
  File "D:\Project\Website\venv\lib\site-packages\django\core\handlers\base.py", line 124, in _get_response
    response = wrapped_callback(request, *callback_args, **callback_kwargs)
  File "D:\Project\Website\staticApp\views.py", line 88, in showFont
    with open('./fonts/' + path, mode='rb') as f:
FileNotFoundError: [Errno 2] No such file or directory: './fonts/fontawesome-webfont.woff2'
[2019-03-10 10:20:33,765][Thread-5:302212][task_id:django.request][log.py:228][ERROR][Internal Server Error: /bin/fonts/weathericons-regular-webfont.woff2]
Traceback (most recent call last):
  File "D:\Project\Website\venv\lib\site-packages\django\core\handlers\exception.py", line 34, in inner
    response = get_response(request)
  File "D:\Project\Website\venv\lib\site-packages\django\core\handlers\base.py", line 137, in _get_response
    "returned None instead." % (callback.__module__, view_name)
ValueError: The view staticApp.views.showBin didn't return an HttpResponse object. It returned None instead.
[2019-03-10 10:20:33,870][Thread-5:302212][task_id:root][views.py:74][INFO][Accessing /master.min.css.map with showBin matched nothing.]
[2019-03-10 10:20:33,883][Thread-6:283500][task_id:django.request][log.py:228][WARNING][Not Found: /wp-content/themes/homesite17/fonts/Stanford.woff]
[2019-03-10 10:20:33,871][Thread-5:302212][task_id:django.request][log.py:228][ERROR][Internal Server Error: /bin/master.min.css.map]
Traceback (most recent call last):
  File "D:\Project\Website\venv\lib\site-packages\django\core\handlers\exception.py", line 34, in inner
    response = get_response(request)
  File "D:\Project\Website\venv\lib\site-packages\django\core\handlers\base.py", line 137, in _get_response
    "returned None instead." % (callback.__module__, view_name)
ValueError: The view staticApp.views.showBin didn't return an HttpResponse object. It returned None instead.
[2019-03-10 10:20:33,884][Thread-1:347912][task_id:django.request][log.py:228][ERROR][Internal Server Error: /fonts/fontawesome-webfont.woff]
Traceback (most recent call last):
  File "D:\Project\Website\venv\lib\site-packages\django\core\handlers\exception.py", line 34, in inner
    response = get_response(request)
  File "D:\Project\Website\venv\lib\site-packages\django\core\handlers\base.py", line 126, in _get_response
    response = self.process_exception_by_middleware(e, request)
  File "D:\Project\Website\venv\lib\site-packages\django\core\handlers\base.py", line 124, in _get_response
    response = wrapped_callback(request, *callback_args, **callback_kwargs)
  File "D:\Project\Website\staticApp\views.py", line 88, in showFont
    with open('./fonts/' + path, mode='rb') as f:
FileNotFoundError: [Errno 2] No such file or directory: './fonts/fontawesome-webfont.woff'
[2019-03-10 10:20:33,992][Thread-1:347912][task_id:root][views.py:74][INFO][Accessing /fonts/weathericons-regular-webfont.woff with showBin matched nothing.]
[2019-03-10 10:20:33,993][Thread-1:347912][task_id:django.request][log.py:228][ERROR][Internal Server Error: /bin/fonts/weathericons-regular-webfont.woff]
Traceback (most recent call last):
  File "D:\Project\Website\venv\lib\site-packages\django\core\handlers\exception.py", line 34, in inner
    response = get_response(request)
  File "D:\Project\Website\venv\lib\site-packages\django\core\handlers\base.py", line 137, in _get_response
    "returned None instead." % (callback.__module__, view_name)
ValueError: The view staticApp.views.showBin didn't return an HttpResponse object. It returned None instead.
[2019-03-10 10:20:34,096][Thread-1:347912][task_id:django.request][log.py:228][ERROR][Internal Server Error: /fonts/fontawesome-webfont.ttf]
Traceback (most recent call last):
  File "D:\Project\Website\venv\lib\site-packages\django\core\handlers\exception.py", line 34, in inner
    response = get_response(request)
  File "D:\Project\Website\venv\lib\site-packages\django\core\handlers\base.py", line 126, in _get_response
    response = self.process_exception_by_middleware(e, request)
  File "D:\Project\Website\venv\lib\site-packages\django\core\handlers\base.py", line 124, in _get_response
    response = wrapped_callback(request, *callback_args, **callback_kwargs)
  File "D:\Project\Website\staticApp\views.py", line 88, in showFont
    with open('./fonts/' + path, mode='rb') as f:
FileNotFoundError: [Errno 2] No such file or directory: './fonts/fontawesome-webfont.ttf'
[2019-03-10 10:20:34,325][Thread-1:347912][task_id:root][views.py:74][INFO][Accessing /fonts/weathericons-regular-webfont.ttf with showBin matched nothing.]
[2019-03-10 10:20:34,325][Thread-1:347912][task_id:django.request][log.py:228][ERROR][Internal Server Error: /bin/fonts/weathericons-regular-webfont.ttf]
Traceback (most recent call last):
  File "D:\Project\Website\venv\lib\site-packages\django\core\handlers\exception.py", line 34, in inner
    response = get_response(request)
  File "D:\Project\Website\venv\lib\site-packages\django\core\handlers\base.py", line 137, in _get_response
    "returned None instead." % (callback.__module__, view_name)
ValueError: The view staticApp.views.showBin didn't return an HttpResponse object. It returned None instead.
[2019-03-10 10:21:13,136][Thread-1:347912][task_id:root][views.py:12][INFO][Accessing Page home/ with showHome]
[2019-03-10 10:21:13,487][Thread-3:275668][task_id:django.request][log.py:228][WARNING][Not Found: /wp-content/themes/homesite17/fonts/Stanford.ttf]
[2019-03-10 10:21:13,489][Thread-6:283500][task_id:root][views.py:74][INFO][Accessing /fonts/weathericons-regular-webfont.woff2 with showBin matched nothing.]
[2019-03-10 10:21:13,490][Thread-6:283500][task_id:django.request][log.py:228][ERROR][Internal Server Error: /bin/fonts/weathericons-regular-webfont.woff2]
Traceback (most recent call last):
  File "D:\Project\Website\venv\lib\site-packages\django\core\handlers\exception.py", line 34, in inner
    response = get_response(request)
  File "D:\Project\Website\venv\lib\site-packages\django\core\handlers\base.py", line 137, in _get_response
    "returned None instead." % (callback.__module__, view_name)
ValueError: The view staticApp.views.showBin didn't return an HttpResponse object. It returned None instead.
[2019-03-10 10:21:13,585][Thread-6:283500][task_id:root][views.py:74][INFO][Accessing /master.min.css.map with showBin matched nothing.]
[2019-03-10 10:21:13,604][Thread-3:275668][task_id:root][views.py:74][INFO][Accessing /fonts/weathericons-regular-webfont.woff with showBin matched nothing.]
[2019-03-10 10:21:13,606][Thread-5:302212][task_id:django.request][log.py:228][WARNING][Not Found: /wp-content/themes/homesite17/fonts/Stanford.woff]
[2019-03-10 10:21:13,586][Thread-6:283500][task_id:django.request][log.py:228][ERROR][Internal Server Error: /bin/master.min.css.map]
Traceback (most recent call last):
  File "D:\Project\Website\venv\lib\site-packages\django\core\handlers\exception.py", line 34, in inner
    response = get_response(request)
  File "D:\Project\Website\venv\lib\site-packages\django\core\handlers\base.py", line 137, in _get_response
    "returned None instead." % (callback.__module__, view_name)
ValueError: The view staticApp.views.showBin didn't return an HttpResponse object. It returned None instead.
[2019-03-10 10:21:13,611][Thread-3:275668][task_id:django.request][log.py:228][ERROR][Internal Server Error: /bin/fonts/weathericons-regular-webfont.woff]
Traceback (most recent call last):
  File "D:\Project\Website\venv\lib\site-packages\django\core\handlers\exception.py", line 34, in inner
    response = get_response(request)
  File "D:\Project\Website\venv\lib\site-packages\django\core\handlers\base.py", line 137, in _get_response
    "returned None instead." % (callback.__module__, view_name)
ValueError: The view staticApp.views.showBin didn't return an HttpResponse object. It returned None instead.
[2019-03-10 10:21:13,723][Thread-3:275668][task_id:root][views.py:74][INFO][Accessing /fonts/weathericons-regular-webfont.ttf with showBin matched nothing.]
[2019-03-10 10:21:13,723][Thread-3:275668][task_id:django.request][log.py:228][ERROR][Internal Server Error: /bin/fonts/weathericons-regular-webfont.ttf]
Traceback (most recent call last):
  File "D:\Project\Website\venv\lib\site-packages\django\core\handlers\exception.py", line 34, in inner
    response = get_response(request)
  File "D:\Project\Website\venv\lib\site-packages\django\core\handlers\base.py", line 137, in _get_response
    "returned None instead." % (callback.__module__, view_name)
ValueError: The view staticApp.views.showBin didn't return an HttpResponse object. It returned None instead.
[2019-03-10 10:24:58,546][Thread-3:275668][task_id:root][views.py:74][INFO][Accessing /fonts/weathericons-regular-webfont.woff2 with showBin matched nothing.]
[2019-03-10 10:24:58,546][Thread-3:275668][task_id:django.request][log.py:228][ERROR][Internal Server Error: /bin/fonts/weathericons-regular-webfont.woff2]
Traceback (most recent call last):
  File "D:\Project\Website\venv\lib\site-packages\django\core\handlers\exception.py", line 34, in inner
    response = get_response(request)
  File "D:\Project\Website\venv\lib\site-packages\django\core\handlers\base.py", line 137, in _get_response
    "returned None instead." % (callback.__module__, view_name)
ValueError: The view staticApp.views.showBin didn't return an HttpResponse object. It returned None instead.
[2019-03-10 10:24:58,851][Thread-3:275668][task_id:root][views.py:74][INFO][Accessing /fonts/weathericons-regular-webfont.woff with showBin matched nothing.]
[2019-03-10 10:24:58,852][Thread-3:275668][task_id:django.request][log.py:228][ERROR][Internal Server Error: /bin/fonts/weathericons-regular-webfont.woff]
Traceback (most recent call last):
  File "D:\Project\Website\venv\lib\site-packages\django\core\handlers\exception.py", line 34, in inner
    response = get_response(request)
  File "D:\Project\Website\venv\lib\site-packages\django\core\handlers\base.py", line 137, in _get_response
    "returned None instead." % (callback.__module__, view_name)
ValueError: The view staticApp.views.showBin didn't return an HttpResponse object. It returned None instead.
[2019-03-10 10:25:00,200][Thread-3:275668][task_id:root][views.py:74][INFO][Accessing /fonts/weathericons-regular-webfont.woff2 with showBin matched nothing.]
[2019-03-10 10:25:00,201][Thread-3:275668][task_id:django.request][log.py:228][ERROR][Internal Server Error: /bin/fonts/weathericons-regular-webfont.woff2]
Traceback (most recent call last):
  File "D:\Project\Website\venv\lib\site-packages\django\core\handlers\exception.py", line 34, in inner
    response = get_response(request)
  File "D:\Project\Website\venv\lib\site-packages\django\core\handlers\base.py", line 137, in _get_response
    "returned None instead." % (callback.__module__, view_name)
ValueError: The view staticApp.views.showBin didn't return an HttpResponse object. It returned None instead.
[2019-03-10 10:25:00,410][Thread-3:275668][task_id:root][views.py:74][INFO][Accessing /fonts/weathericons-regular-webfont.woff with showBin matched nothing.]
[2019-03-10 10:25:00,411][Thread-3:275668][task_id:django.request][log.py:228][ERROR][Internal Server Error: /bin/fonts/weathericons-regular-webfont.woff]
Traceback (most recent call last):
  File "D:\Project\Website\venv\lib\site-packages\django\core\handlers\exception.py", line 34, in inner
    response = get_response(request)
  File "D:\Project\Website\venv\lib\site-packages\django\core\handlers\base.py", line 137, in _get_response
    "returned None instead." % (callback.__module__, view_name)
ValueError: The view staticApp.views.showBin didn't return an HttpResponse object. It returned None instead.
[2019-03-10 10:25:02,655][Thread-6:283500][task_id:root][views.py:74][INFO][Accessing /master.min.css.map with showBin matched nothing.]
[2019-03-10 10:25:02,655][Thread-6:283500][task_id:django.request][log.py:228][ERROR][Internal Server Error: /bin/master.min.css.map]
Traceback (most recent call last):
  File "D:\Project\Website\venv\lib\site-packages\django\core\handlers\exception.py", line 34, in inner
    response = get_response(request)
  File "D:\Project\Website\venv\lib\site-packages\django\core\handlers\base.py", line 137, in _get_response
    "returned None instead." % (callback.__module__, view_name)
ValueError: The view staticApp.views.showBin didn't return an HttpResponse object. It returned None instead.
[2019-03-10 10:25:24,372][Thread-6:283500][task_id:root][views.py:12][INFO][Accessing Page home/ with showHome]
[2019-03-10 10:25:24,666][Thread-4:317848][task_id:django.request][log.py:228][WARNING][Not Found: /wp-content/themes/homesite17/fonts/Stanford.ttf]
[2019-03-10 10:25:24,668][Thread-1:347912][task_id:root][views.py:74][INFO][Accessing /fonts/weathericons-regular-webfont.woff2 with showBin matched nothing.]
[2019-03-10 10:25:24,669][Thread-1:347912][task_id:django.request][log.py:228][ERROR][Internal Server Error: /bin/fonts/weathericons-regular-webfont.woff2]
Traceback (most recent call last):
  File "D:\Project\Website\venv\lib\site-packages\django\core\handlers\exception.py", line 34, in inner
    response = get_response(request)
  File "D:\Project\Website\venv\lib\site-packages\django\core\handlers\base.py", line 137, in _get_response
    "returned None instead." % (callback.__module__, view_name)
ValueError: The view staticApp.views.showBin didn't return an HttpResponse object. It returned None instead.
[2019-03-10 10:25:24,784][Thread-1:347912][task_id:root][views.py:74][INFO][Accessing /master.min.css.map with showBin matched nothing.]
[2019-03-10 10:25:24,809][Thread-4:317848][task_id:root][views.py:74][INFO][Accessing /fonts/weathericons-regular-webfont.woff with showBin matched nothing.]
[2019-03-10 10:25:24,810][Thread-3:275668][task_id:django.request][log.py:228][WARNING][Not Found: /wp-content/themes/homesite17/fonts/Stanford.woff]
[2019-03-10 10:25:24,785][Thread-1:347912][task_id:django.request][log.py:228][ERROR][Internal Server Error: /bin/master.min.css.map]
Traceback (most recent call last):
  File "D:\Project\Website\venv\lib\site-packages\django\core\handlers\exception.py", line 34, in inner
    response = get_response(request)
  File "D:\Project\Website\venv\lib\site-packages\django\core\handlers\base.py", line 137, in _get_response
    "returned None instead." % (callback.__module__, view_name)
ValueError: The view staticApp.views.showBin didn't return an HttpResponse object. It returned None instead.
[2019-03-10 10:25:24,816][Thread-4:317848][task_id:django.request][log.py:228][ERROR][Internal Server Error: /bin/fonts/weathericons-regular-webfont.woff]
Traceback (most recent call last):
  File "D:\Project\Website\venv\lib\site-packages\django\core\handlers\exception.py", line 34, in inner
    response = get_response(request)
  File "D:\Project\Website\venv\lib\site-packages\django\core\handlers\base.py", line 137, in _get_response
    "returned None instead." % (callback.__module__, view_name)
ValueError: The view staticApp.views.showBin didn't return an HttpResponse object. It returned None instead.
[2019-03-10 10:25:24,916][Thread-4:317848][task_id:root][views.py:74][INFO][Accessing /fonts/weathericons-regular-webfont.ttf with showBin matched nothing.]
[2019-03-10 10:25:24,917][Thread-4:317848][task_id:django.request][log.py:228][ERROR][Internal Server Error: /bin/fonts/weathericons-regular-webfont.ttf]
Traceback (most recent call last):
  File "D:\Project\Website\venv\lib\site-packages\django\core\handlers\exception.py", line 34, in inner
    response = get_response(request)
  File "D:\Project\Website\venv\lib\site-packages\django\core\handlers\base.py", line 137, in _get_response
    "returned None instead." % (callback.__module__, view_name)
ValueError: The view staticApp.views.showBin didn't return an HttpResponse object. It returned None instead.
[2019-03-10 10:27:48,368][Thread-1:275992][task_id:root][views.py:12][INFO][Accessing Page home/ with showHome]
[2019-03-10 10:27:48,726][Thread-3:353624][task_id:django.request][log.py:228][WARNING][Not Found: /wp-content/themes/homesite17/fonts/Stanford.ttf]
[2019-03-10 10:27:48,730][Thread-6:287708][task_id:django.request][log.py:228][ERROR][Internal Server Error: /bin/fonts/weathericons-regular-webfont.woff2]
Traceback (most recent call last):
  File "D:\Project\Website\venv\lib\site-packages\django\core\handlers\exception.py", line 34, in inner
    response = get_response(request)
  File "D:\Project\Website\venv\lib\site-packages\django\core\handlers\base.py", line 126, in _get_response
    response = self.process_exception_by_middleware(e, request)
  File "D:\Project\Website\venv\lib\site-packages\django\core\handlers\base.py", line 124, in _get_response
    response = wrapped_callback(request, *callback_args, **callback_kwargs)
  File "D:\Project\Website\staticApp\views.py", line 75, in showBin
    with open('./fonts/' + path, mode="rb") as f:
FileNotFoundError: [Errno 2] No such file or directory: './fonts/fonts/weathericons-regular-webfont.woff2'
[2019-03-10 10:27:49,004][Thread-6:287708][task_id:root][views.py:84][INFO][Accessing /master.min.css.map with showBin matched nothing.]
[2019-03-10 10:27:49,004][Thread-6:287708][task_id:django.request][log.py:228][ERROR][Internal Server Error: /bin/master.min.css.map]
Traceback (most recent call last):
  File "D:\Project\Website\venv\lib\site-packages\django\core\handlers\exception.py", line 34, in inner
    response = get_response(request)
  File "D:\Project\Website\venv\lib\site-packages\django\core\handlers\base.py", line 137, in _get_response
    "returned None instead." % (callback.__module__, view_name)
ValueError: The view staticApp.views.showBin didn't return an HttpResponse object. It returned None instead.
[2019-03-10 10:27:49,046][Thread-6:287708][task_id:django.request][log.py:228][WARNING][Not Found: /wp-content/themes/homesite17/fonts/Stanford.woff]
[2019-03-10 10:27:49,050][Thread-3:353624][task_id:django.request][log.py:228][ERROR][Internal Server Error: /bin/fonts/weathericons-regular-webfont.woff]
Traceback (most recent call last):
  File "D:\Project\Website\venv\lib\site-packages\django\core\handlers\exception.py", line 34, in inner
    response = get_response(request)
  File "D:\Project\Website\venv\lib\site-packages\django\core\handlers\base.py", line 126, in _get_response
    response = self.process_exception_by_middleware(e, request)
  File "D:\Project\Website\venv\lib\site-packages\django\core\handlers\base.py", line 124, in _get_response
    response = wrapped_callback(request, *callback_args, **callback_kwargs)
  File "D:\Project\Website\staticApp\views.py", line 75, in showBin
    with open('./fonts/' + path, mode="rb") as f:
FileNotFoundError: [Errno 2] No such file or directory: './fonts/fonts/weathericons-regular-webfont.woff'
[2019-03-10 10:27:49,186][Thread-3:353624][task_id:django.request][log.py:228][ERROR][Internal Server Error: /bin/fonts/weathericons-regular-webfont.ttf]
Traceback (most recent call last):
  File "D:\Project\Website\venv\lib\site-packages\django\core\handlers\exception.py", line 34, in inner
    response = get_response(request)
  File "D:\Project\Website\venv\lib\site-packages\django\core\handlers\base.py", line 126, in _get_response
    response = self.process_exception_by_middleware(e, request)
  File "D:\Project\Website\venv\lib\site-packages\django\core\handlers\base.py", line 124, in _get_response
    response = wrapped_callback(request, *callback_args, **callback_kwargs)
  File "D:\Project\Website\staticApp\views.py", line 80, in showBin
    with open('./fonts/' + path, mode="rb") as f:
FileNotFoundError: [Errno 2] No such file or directory: './fonts/fonts/weathericons-regular-webfont.ttf'
[2019-03-10 10:28:01,500][Thread-3:353624][task_id:root][views.py:12][INFO][Accessing Page home/ with showHome]
[2019-03-10 10:28:01,770][Thread-5:293328][task_id:django.request][log.py:228][WARNING][Not Found: /wp-content/themes/homesite17/fonts/Stanford.ttf]
[2019-03-10 10:28:01,773][Thread-1:275992][task_id:django.request][log.py:228][ERROR][Internal Server Error: /bin/fonts/weathericons-regular-webfont.woff2]
Traceback (most recent call last):
  File "D:\Project\Website\venv\lib\site-packages\django\core\handlers\exception.py", line 34, in inner
    response = get_response(request)
  File "D:\Project\Website\venv\lib\site-packages\django\core\handlers\base.py", line 126, in _get_response
    response = self.process_exception_by_middleware(e, request)
  File "D:\Project\Website\venv\lib\site-packages\django\core\handlers\base.py", line 124, in _get_response
    response = wrapped_callback(request, *callback_args, **callback_kwargs)
  File "D:\Project\Website\staticApp\views.py", line 75, in showBin
    with open('./fonts/' + path, mode="rb") as f:
FileNotFoundError: [Errno 2] No such file or directory: './fonts/fonts/weathericons-regular-webfont.woff2'
[2019-03-10 10:28:01,889][Thread-1:275992][task_id:django.request][log.py:228][WARNING][Not Found: /wp-content/themes/homesite17/fonts/Stanford.woff]
[2019-03-10 10:28:01,891][Thread-5:293328][task_id:root][views.py:84][INFO][Accessing /master.min.css.map with showBin matched nothing.]
[2019-03-10 10:28:01,892][Thread-6:287708][task_id:django.request][log.py:228][ERROR][Internal Server Error: /bin/fonts/weathericons-regular-webfont.woff]
Traceback (most recent call last):
  File "D:\Project\Website\venv\lib\site-packages\django\core\handlers\exception.py", line 34, in inner
    response = get_response(request)
  File "D:\Project\Website\venv\lib\site-packages\django\core\handlers\base.py", line 126, in _get_response
    response = self.process_exception_by_middleware(e, request)
  File "D:\Project\Website\venv\lib\site-packages\django\core\handlers\base.py", line 124, in _get_response
    response = wrapped_callback(request, *callback_args, **callback_kwargs)
  File "D:\Project\Website\staticApp\views.py", line 75, in showBin
    with open('./fonts/' + path, mode="rb") as f:
FileNotFoundError: [Errno 2] No such file or directory: './fonts/fonts/weathericons-regular-webfont.woff'
[2019-03-10 10:28:01,893][Thread-5:293328][task_id:django.request][log.py:228][ERROR][Internal Server Error: /bin/master.min.css.map]
Traceback (most recent call last):
  File "D:\Project\Website\venv\lib\site-packages\django\core\handlers\exception.py", line 34, in inner
    response = get_response(request)
  File "D:\Project\Website\venv\lib\site-packages\django\core\handlers\base.py", line 137, in _get_response
    "returned None instead." % (callback.__module__, view_name)
ValueError: The view staticApp.views.showBin didn't return an HttpResponse object. It returned None instead.
[2019-03-10 10:28:02,211][Thread-5:293328][task_id:django.request][log.py:228][ERROR][Internal Server Error: /bin/fonts/weathericons-regular-webfont.ttf]
Traceback (most recent call last):
  File "D:\Project\Website\venv\lib\site-packages\django\core\handlers\exception.py", line 34, in inner
    response = get_response(request)
  File "D:\Project\Website\venv\lib\site-packages\django\core\handlers\base.py", line 126, in _get_response
    response = self.process_exception_by_middleware(e, request)
  File "D:\Project\Website\venv\lib\site-packages\django\core\handlers\base.py", line 124, in _get_response
    response = wrapped_callback(request, *callback_args, **callback_kwargs)
  File "D:\Project\Website\staticApp\views.py", line 80, in showBin
    with open('./fonts/' + path, mode="rb") as f:
FileNotFoundError: [Errno 2] No such file or directory: './fonts/fonts/weathericons-regular-webfont.ttf'
[2019-03-10 10:28:44,376][Thread-1:284476][task_id:root][views.py:12][INFO][Accessing Page home/ with showHome]
[2019-03-10 10:28:44,745][Thread-5:293080][task_id:django.request][log.py:228][WARNING][Not Found: /wp-content/themes/homesite17/fonts/Stanford.ttf]
[2019-03-10 10:28:44,746][Thread-3:291700][task_id:django.request][log.py:228][ERROR][Internal Server Error: /fonts/fontawesome-webfont.woff2]
Traceback (most recent call last):
  File "D:\Project\Website\venv\lib\site-packages\django\core\handlers\exception.py", line 34, in inner
    response = get_response(request)
  File "D:\Project\Website\venv\lib\site-packages\django\core\handlers\base.py", line 126, in _get_response
    response = self.process_exception_by_middleware(e, request)
  File "D:\Project\Website\venv\lib\site-packages\django\core\handlers\base.py", line 124, in _get_response
    response = wrapped_callback(request, *callback_args, **callback_kwargs)
  File "D:\Project\Website\staticApp\views.py", line 75, in showBin
    with open('./' + path, mode="rb") as f:
FileNotFoundError: [Errno 2] No such file or directory: './fontawesome-webfont.woff2'
[2019-03-10 10:28:44,839][Thread-3:291700][task_id:django.request][log.py:228][WARNING][Not Found: /wp-content/themes/homesite17/fonts/Stanford.woff]
[2019-03-10 10:28:44,840][Thread-1:284476][task_id:root][views.py:84][INFO][Accessing /master.min.css.map with showBin matched nothing.]
[2019-03-10 10:28:44,840][Thread-1:284476][task_id:django.request][log.py:228][ERROR][Internal Server Error: /bin/master.min.css.map]
Traceback (most recent call last):
  File "D:\Project\Website\venv\lib\site-packages\django\core\handlers\exception.py", line 34, in inner
    response = get_response(request)
  File "D:\Project\Website\venv\lib\site-packages\django\core\handlers\base.py", line 137, in _get_response
    "returned None instead." % (callback.__module__, view_name)
ValueError: The view staticApp.views.showBin didn't return an HttpResponse object. It returned None instead.
[2019-03-10 10:28:44,907][Thread-1:284476][task_id:django.request][log.py:228][ERROR][Internal Server Error: /fonts/fontawesome-webfont.woff]
Traceback (most recent call last):
  File "D:\Project\Website\venv\lib\site-packages\django\core\handlers\exception.py", line 34, in inner
    response = get_response(request)
  File "D:\Project\Website\venv\lib\site-packages\django\core\handlers\base.py", line 126, in _get_response
    response = self.process_exception_by_middleware(e, request)
  File "D:\Project\Website\venv\lib\site-packages\django\core\handlers\base.py", line 124, in _get_response
    response = wrapped_callback(request, *callback_args, **callback_kwargs)
  File "D:\Project\Website\staticApp\views.py", line 75, in showBin
    with open('./' + path, mode="rb") as f:
FileNotFoundError: [Errno 2] No such file or directory: './fontawesome-webfont.woff'
[2019-03-10 10:28:45,079][Thread-1:284476][task_id:django.request][log.py:228][ERROR][Internal Server Error: /fonts/fontawesome-webfont.ttf]
Traceback (most recent call last):
  File "D:\Project\Website\venv\lib\site-packages\django\core\handlers\exception.py", line 34, in inner
    response = get_response(request)
  File "D:\Project\Website\venv\lib\site-packages\django\core\handlers\base.py", line 126, in _get_response
    response = self.process_exception_by_middleware(e, request)
  File "D:\Project\Website\venv\lib\site-packages\django\core\handlers\base.py", line 124, in _get_response
    response = wrapped_callback(request, *callback_args, **callback_kwargs)
  File "D:\Project\Website\staticApp\views.py", line 80, in showBin
    with open('./' + path, mode="rb") as f:
FileNotFoundError: [Errno 2] No such file or directory: './fontawesome-webfont.ttf'
[2019-03-10 10:31:12,550][Thread-1:277548][task_id:root][views.py:12][INFO][Accessing Page home/ with showHome]
[2019-03-10 10:31:12,910][Thread-3:291680][task_id:django.request][log.py:228][WARNING][Not Found: /wp-content/themes/homesite17/fonts/Stanford.ttf]
[2019-03-10 10:31:12,910][Thread-6:321668][task_id:django.request][log.py:228][ERROR][Internal Server Error: /fonts/fontawesome-webfont.woff2]
Traceback (most recent call last):
  File "D:\Project\Website\venv\lib\site-packages\django\core\handlers\exception.py", line 34, in inner
    response = get_response(request)
  File "D:\Project\Website\venv\lib\site-packages\django\core\handlers\base.py", line 126, in _get_response
    response = self.process_exception_by_middleware(e, request)
  File "D:\Project\Website\venv\lib\site-packages\django\core\handlers\base.py", line 124, in _get_response
    response = wrapped_callback(request, *callback_args, **callback_kwargs)
  File "D:\Project\Website\staticApp\views.py", line 89, in showFont
    with open('./bin/' + path, mode="rb") as f:
FileNotFoundError: [Errno 2] No such file or directory: './bin/fontawesome-webfont.woff2'
[2019-03-10 10:31:13,012][Thread-6:321668][task_id:root][views.py:84][INFO][Accessing /master.min.css.map with showBin matched nothing.]
[2019-03-10 10:31:13,016][Thread-3:291680][task_id:django.request][log.py:228][WARNING][Not Found: /wp-content/themes/homesite17/fonts/Stanford.woff]
[2019-03-10 10:31:13,016][Thread-6:321668][task_id:django.request][log.py:228][ERROR][Internal Server Error: /bin/master.min.css.map]
Traceback (most recent call last):
  File "D:\Project\Website\venv\lib\site-packages\django\core\handlers\exception.py", line 34, in inner
    response = get_response(request)
  File "D:\Project\Website\venv\lib\site-packages\django\core\handlers\base.py", line 137, in _get_response
    "returned None instead." % (callback.__module__, view_name)
ValueError: The view staticApp.views.showBin didn't return an HttpResponse object. It returned None instead.
[2019-03-10 10:31:13,085][Thread-6:321668][task_id:django.request][log.py:228][ERROR][Internal Server Error: /fonts/fontawesome-webfont.woff]
Traceback (most recent call last):
  File "D:\Project\Website\venv\lib\site-packages\django\core\handlers\exception.py", line 34, in inner
    response = get_response(request)
  File "D:\Project\Website\venv\lib\site-packages\django\core\handlers\base.py", line 126, in _get_response
    response = self.process_exception_by_middleware(e, request)
  File "D:\Project\Website\venv\lib\site-packages\django\core\handlers\base.py", line 124, in _get_response
    response = wrapped_callback(request, *callback_args, **callback_kwargs)
  File "D:\Project\Website\staticApp\views.py", line 89, in showFont
    with open('./bin/' + path, mode="rb") as f:
FileNotFoundError: [Errno 2] No such file or directory: './bin/fontawesome-webfont.woff'
[2019-03-10 10:31:13,242][Thread-6:321668][task_id:django.request][log.py:228][ERROR][Internal Server Error: /fonts/fontawesome-webfont.ttf]
Traceback (most recent call last):
  File "D:\Project\Website\venv\lib\site-packages\django\core\handlers\exception.py", line 34, in inner
    response = get_response(request)
  File "D:\Project\Website\venv\lib\site-packages\django\core\handlers\base.py", line 126, in _get_response
    response = self.process_exception_by_middleware(e, request)
  File "D:\Project\Website\venv\lib\site-packages\django\core\handlers\base.py", line 124, in _get_response
    response = wrapped_callback(request, *callback_args, **callback_kwargs)
  File "D:\Project\Website\staticApp\views.py", line 94, in showFont
    with open('./bin/' + path, mode="rb") as f:
FileNotFoundError: [Errno 2] No such file or directory: './bin/fontawesome-webfont.ttf'
[2019-03-10 10:31:30,751][Thread-1:338476][task_id:root][views.py:12][INFO][Accessing Page home/ with showHome]
[2019-03-10 10:31:31,097][Thread-6:289936][task_id:django.request][log.py:228][WARNING][Not Found: /wp-content/themes/homesite17/fonts/Stanford.ttf]
[2019-03-10 10:31:31,187][Thread-6:289936][task_id:root][views.py:84][INFO][Accessing /master.min.css.map with showBin matched nothing.]
[2019-03-10 10:31:31,193][Thread-3:352456][task_id:django.request][log.py:228][WARNING][Not Found: /wp-content/themes/homesite17/fonts/Stanford.woff]
[2019-03-10 10:31:31,190][Thread-6:289936][task_id:django.request][log.py:228][ERROR][Internal Server Error: /bin/master.min.css.map]
Traceback (most recent call last):
  File "D:\Project\Website\venv\lib\site-packages\django\core\handlers\exception.py", line 34, in inner
    response = get_response(request)
  File "D:\Project\Website\venv\lib\site-packages\django\core\handlers\base.py", line 137, in _get_response
    "returned None instead." % (callback.__module__, view_name)
ValueError: The view staticApp.views.showBin didn't return an HttpResponse object. It returned None instead.
[2019-03-10 10:33:53,990][Thread-1:353664][task_id:root][views.py:12][INFO][Accessing Page home/ with showHome]
[2019-03-10 10:33:54,299][Thread-3:349392][task_id:django.request][log.py:228][WARNING][Not Found: /wp-content/themes/homesite17/fonts/Stanford.ttf]
[2019-03-10 10:33:54,568][Thread-1:353664][task_id:django.request][log.py:228][WARNING][Not Found: /wp-content/themes/homesite17/fonts/Stanford.woff]
[2019-03-10 10:34:54,176][Thread-3:349392][task_id:root][views.py:84][INFO][Accessing /master.min.css.map with showBin matched nothing.]
[2019-03-10 10:34:54,177][Thread-3:349392][task_id:django.request][log.py:228][ERROR][Internal Server Error: /bin/master.min.css.map]
Traceback (most recent call last):
  File "D:\Project\Website\venv\lib\site-packages\django\core\handlers\exception.py", line 34, in inner
    response = get_response(request)
  File "D:\Project\Website\venv\lib\site-packages\django\core\handlers\base.py", line 137, in _get_response
    "returned None instead." % (callback.__module__, view_name)
ValueError: The view staticApp.views.showBin didn't return an HttpResponse object. It returned None instead.
[2019-03-10 10:35:06,279][Thread-3:349392][task_id:root][views.py:12][INFO][Accessing Page home/ with showHome]
[2019-03-10 10:35:06,606][Thread-1:353664][task_id:django.request][log.py:228][WARNING][Not Found: /wp-content/themes/homesite17/fonts/Stanford.ttf]
[2019-03-10 10:35:06,757][Thread-8:352704][task_id:django.request][log.py:228][WARNING][Not Found: /wp-content/themes/homesite17/fonts/Stanford.woff]
[2019-03-10 10:35:06,786][Thread-8:352704][task_id:root][views.py:84][INFO][Accessing /master.min.css.map with showBin matched nothing.]
[2019-03-10 10:35:06,787][Thread-8:352704][task_id:django.request][log.py:228][ERROR][Internal Server Error: /bin/master.min.css.map]
Traceback (most recent call last):
  File "D:\Project\Website\venv\lib\site-packages\django\core\handlers\exception.py", line 34, in inner
    response = get_response(request)
  File "D:\Project\Website\venv\lib\site-packages\django\core\handlers\base.py", line 137, in _get_response
    "returned None instead." % (callback.__module__, view_name)
ValueError: The view staticApp.views.showBin didn't return an HttpResponse object. It returned None instead.
[2019-03-10 10:46:43,632][Thread-1:348600][task_id:root][views.py:12][INFO][Accessing Page home/ with showHome]
[2019-03-10 10:46:43,995][Thread-3:353876][task_id:django.request][log.py:228][WARNING][Not Found: /wp-content/themes/homesite17/fonts/Stanford.ttf]
[2019-03-10 10:46:44,152][Thread-3:353876][task_id:root][views.py:84][INFO][Accessing /master.min.css.map with showBin matched nothing.]
[2019-03-10 10:46:44,153][Thread-3:353876][task_id:django.request][log.py:228][ERROR][Internal Server Error: /bin/master.min.css.map]
Traceback (most recent call last):
  File "D:\Project\Website\venv\lib\site-packages\django\core\handlers\exception.py", line 34, in inner
    response = get_response(request)
  File "D:\Project\Website\venv\lib\site-packages\django\core\handlers\base.py", line 137, in _get_response
    "returned None instead." % (callback.__module__, view_name)
ValueError: The view staticApp.views.showBin didn't return an HttpResponse object. It returned None instead.
[2019-03-10 10:46:44,252][Thread-3:353876][task_id:django.request][log.py:228][WARNING][Not Found: /wp-content/themes/homesite17/fonts/Stanford.woff]
[2019-03-10 10:49:02,243][Thread-1:353776][task_id:root][views.py:12][INFO][Accessing Page home/ with showHome]
[2019-03-10 10:49:02,641][Thread-6:353864][task_id:django.request][log.py:228][WARNING][Not Found: /wp-content/themes/homesite17/fonts/Stanford.ttf]
[2019-03-10 10:49:02,739][Thread-6:353864][task_id:root][views.py:84][INFO][Accessing /master.min.css.map with showBin matched nothing.]
[2019-03-10 10:49:02,740][Thread-6:353864][task_id:django.request][log.py:228][ERROR][Internal Server Error: /bin/master.min.css.map]
Traceback (most recent call last):
  File "D:\Project\Website\venv\lib\site-packages\django\core\handlers\exception.py", line 34, in inner
    response = get_response(request)
  File "D:\Project\Website\venv\lib\site-packages\django\core\handlers\base.py", line 137, in _get_response
    "returned None instead." % (callback.__module__, view_name)
ValueError: The view staticApp.views.showBin didn't return an HttpResponse object. It returned None instead.
[2019-03-10 10:49:02,856][Thread-6:353864][task_id:django.request][log.py:228][WARNING][Not Found: /wp-content/themes/homesite17/fonts/Stanford.woff]
[2019-03-10 10:49:34,490][Thread-7:352592][task_id:root][views.py:12][INFO][Accessing Page home/ with showHome]
[2019-03-10 10:49:34,795][Thread-8:291560][task_id:django.request][log.py:228][WARNING][Not Found: /wp-content/themes/homesite17/fonts/Stanford.ttf]
[2019-03-10 10:49:34,912][Thread-11:353412][task_id:root][views.py:84][INFO][Accessing /master.min.css.map with showBin matched nothing.]
[2019-03-10 10:49:34,916][Thread-10:342176][task_id:django.request][log.py:228][WARNING][Not Found: /wp-content/themes/homesite17/fonts/Stanford.woff]
[2019-03-10 10:49:34,913][Thread-11:353412][task_id:django.request][log.py:228][ERROR][Internal Server Error: /bin/master.min.css.map]
Traceback (most recent call last):
  File "D:\Project\Website\venv\lib\site-packages\django\core\handlers\exception.py", line 34, in inner
    response = get_response(request)
  File "D:\Project\Website\venv\lib\site-packages\django\core\handlers\base.py", line 137, in _get_response
    "returned None instead." % (callback.__module__, view_name)
ValueError: The view staticApp.views.showBin didn't return an HttpResponse object. It returned None instead.
[2019-03-10 10:53:12,613][Thread-1:354968][task_id:root][views.py:12][INFO][Accessing Page home/ with showHome]
[2019-03-10 10:53:12,961][Thread-3:354984][task_id:django.request][log.py:228][WARNING][Not Found: /wp-content/themes/homesite17/fonts/Stanford.ttf]
[2019-03-10 10:53:13,064][Thread-3:354984][task_id:root][views.py:84][INFO][Accessing /master.min.css.map with showBin matched nothing.]
[2019-03-10 10:53:13,065][Thread-3:354984][task_id:django.request][log.py:228][ERROR][Internal Server Error: /bin/master.min.css.map]
Traceback (most recent call last):
  File "D:\Project\Website\venv\lib\site-packages\django\core\handlers\exception.py", line 34, in inner
    response = get_response(request)
  File "D:\Project\Website\venv\lib\site-packages\django\core\handlers\base.py", line 137, in _get_response
    "returned None instead." % (callback.__module__, view_name)
ValueError: The view staticApp.views.showBin didn't return an HttpResponse object. It returned None instead.
[2019-03-10 10:53:13,183][Thread-3:354984][task_id:django.request][log.py:228][WARNING][Not Found: /wp-content/themes/homesite17/fonts/Stanford.woff]
[2019-03-10 10:55:43,633][Thread-8:354352][task_id:root][views.py:84][INFO][Accessing /master.min.css.map with showBin matched nothing.]
[2019-03-10 10:55:43,633][Thread-8:354352][task_id:django.request][log.py:228][ERROR][Internal Server Error: /bin/master.min.css.map]
Traceback (most recent call last):
  File "D:\Project\Website\venv\lib\site-packages\django\core\handlers\exception.py", line 34, in inner
    response = get_response(request)
  File "D:\Project\Website\venv\lib\site-packages\django\core\handlers\base.py", line 137, in _get_response
    "returned None instead." % (callback.__module__, view_name)
ValueError: The view staticApp.views.showBin didn't return an HttpResponse object. It returned None instead.
[2019-03-10 10:56:21,770][Thread-9:351924][task_id:root][views.py:12][INFO][Accessing Page home/ with showHome]
[2019-03-10 10:56:22,135][Thread-12:278000][task_id:django.request][log.py:228][WARNING][Not Found: /wp-content/themes/homesite17/fonts/Stanford.ttf]
[2019-03-10 10:56:22,288][Thread-11:352156][task_id:django.request][log.py:228][WARNING][Not Found: /wp-content/themes/homesite17/fonts/Stanford.woff]
[2019-03-10 10:56:22,289][Thread-10:354560][task_id:root][views.py:84][INFO][Accessing /master.min.css.map with showBin matched nothing.]
[2019-03-10 10:56:22,291][Thread-10:354560][task_id:django.request][log.py:228][ERROR][Internal Server Error: /bin/master.min.css.map]
Traceback (most recent call last):
  File "D:\Project\Website\venv\lib\site-packages\django\core\handlers\exception.py", line 34, in inner
    response = get_response(request)
  File "D:\Project\Website\venv\lib\site-packages\django\core\handlers\base.py", line 137, in _get_response
    "returned None instead." % (callback.__module__, view_name)
ValueError: The view staticApp.views.showBin didn't return an HttpResponse object. It returned None instead.
[2019-03-10 10:56:36,337][Thread-1:321196][task_id:root][views.py:12][INFO][Accessing Page home/ with showHome]
[2019-03-10 10:56:36,723][Thread-3:354228][task_id:django.request][log.py:228][WARNING][Not Found: /wp-content/themes/homesite17/fonts/Stanford.ttf]
[2019-03-10 10:56:36,988][Thread-3:354228][task_id:root][views.py:84][INFO][Accessing /master.min.css.map with showBin matched nothing.]
[2019-03-10 10:56:37,047][Thread-6:353516][task_id:django.request][log.py:228][WARNING][Not Found: /wp-content/themes/homesite17/fonts/Stanford.woff]
[2019-03-10 10:56:36,989][Thread-3:354228][task_id:django.request][log.py:228][ERROR][Internal Server Error: /bin/master.min.css.map]
Traceback (most recent call last):
  File "D:\Project\Website\venv\lib\site-packages\django\core\handlers\exception.py", line 34, in inner
    response = get_response(request)
  File "D:\Project\Website\venv\lib\site-packages\django\core\handlers\base.py", line 137, in _get_response
    "returned None instead." % (callback.__module__, view_name)
ValueError: The view staticApp.views.showBin didn't return an HttpResponse object. It returned None instead.
[2019-03-10 10:57:53,820][Thread-1:352156][task_id:root][views.py:12][INFO][Accessing Page home/ with showHome]
[2019-03-10 10:57:54,230][Thread-1:352156][task_id:django.request][log.py:228][WARNING][Not Found: /wp-content/themes/homesite17/fonts/Stanford.ttf]
[2019-03-10 10:57:54,230][Thread-6:354064][task_id:django.request][log.py:228][ERROR][Internal Server Error: /fonts/fontawesome-webfont.woff2]
Traceback (most recent call last):
  File "D:\Project\Website\venv\lib\site-packages\django\core\handlers\exception.py", line 34, in inner
    response = get_response(request)
  File "D:\Project\Website\venv\lib\site-packages\django\core\handlers\base.py", line 126, in _get_response
    response = self.process_exception_by_middleware(e, request)
  File "D:\Project\Website\venv\lib\site-packages\django\core\handlers\base.py", line 124, in _get_response
    response = wrapped_callback(request, *callback_args, **callback_kwargs)
  File "D:\Project\Website\staticApp\views.py", line 89, in showFont
    with open('./fonts/' + path, mode="rb") as f:
FileNotFoundError: [Errno 2] No such file or directory: './fonts/fontawesome-webfont.woff2'
[2019-03-10 10:57:54,356][Thread-6:354064][task_id:root][views.py:84][INFO][Accessing /master.css.map with showBin matched nothing.]
[2019-03-10 10:57:54,356][Thread-6:354064][task_id:django.request][log.py:228][ERROR][Internal Server Error: /bin/master.css.map]
Traceback (most recent call last):
  File "D:\Project\Website\venv\lib\site-packages\django\core\handlers\exception.py", line 34, in inner
    response = get_response(request)
  File "D:\Project\Website\venv\lib\site-packages\django\core\handlers\base.py", line 137, in _get_response
    "returned None instead." % (callback.__module__, view_name)
ValueError: The view staticApp.views.showBin didn't return an HttpResponse object. It returned None instead.
[2019-03-10 10:57:54,464][Thread-6:354064][task_id:django.request][log.py:228][WARNING][Not Found: /wp-content/themes/homesite17/fonts/Stanford.woff]
[2019-03-10 10:57:54,550][Thread-6:354064][task_id:django.request][log.py:228][ERROR][Internal Server Error: /fonts/fontawesome-webfont.woff]
Traceback (most recent call last):
  File "D:\Project\Website\venv\lib\site-packages\django\core\handlers\exception.py", line 34, in inner
    response = get_response(request)
  File "D:\Project\Website\venv\lib\site-packages\django\core\handlers\base.py", line 126, in _get_response
    response = self.process_exception_by_middleware(e, request)
  File "D:\Project\Website\venv\lib\site-packages\django\core\handlers\base.py", line 124, in _get_response
    response = wrapped_callback(request, *callback_args, **callback_kwargs)
  File "D:\Project\Website\staticApp\views.py", line 89, in showFont
    with open('./fonts/' + path, mode="rb") as f:
FileNotFoundError: [Errno 2] No such file or directory: './fonts/fontawesome-webfont.woff'
[2019-03-10 10:57:54,698][Thread-6:354064][task_id:django.request][log.py:228][ERROR][Internal Server Error: /fonts/fontawesome-webfont.ttf]
Traceback (most recent call last):
  File "D:\Project\Website\venv\lib\site-packages\django\core\handlers\exception.py", line 34, in inner
    response = get_response(request)
  File "D:\Project\Website\venv\lib\site-packages\django\core\handlers\base.py", line 126, in _get_response
    response = self.process_exception_by_middleware(e, request)
  File "D:\Project\Website\venv\lib\site-packages\django\core\handlers\base.py", line 124, in _get_response
    response = wrapped_callback(request, *callback_args, **callback_kwargs)
  File "D:\Project\Website\staticApp\views.py", line 94, in showFont
    with open('./fonts/' + path, mode="rb") as f:
FileNotFoundError: [Errno 2] No such file or directory: './fonts/fontawesome-webfont.ttf'
[2019-03-10 11:01:03,395][Thread-1:354576][task_id:root][views.py:12][INFO][Accessing Page home/ with showHome]
[2019-03-10 11:01:03,784][Thread-3:354792][task_id:django.request][log.py:228][WARNING][Not Found: /wp-content/themes/homesite17/fonts/Stanford.ttf]
[2019-03-10 11:01:03,925][Thread-3:354792][task_id:django.request][log.py:228][WARNING][Not Found: /wp-content/themes/homesite17/fonts/Stanford.woff]
[2019-03-10 11:01:03,960][Thread-3:354792][task_id:root][views.py:84][INFO][Accessing /master.css.map with showBin matched nothing.]
[2019-03-10 11:01:03,961][Thread-3:354792][task_id:django.request][log.py:228][ERROR][Internal Server Error: /bin/master.css.map]
Traceback (most recent call last):
  File "D:\Project\Website\venv\lib\site-packages\django\core\handlers\exception.py", line 34, in inner
    response = get_response(request)
  File "D:\Project\Website\venv\lib\site-packages\django\core\handlers\base.py", line 137, in _get_response
    "returned None instead." % (callback.__module__, view_name)
ValueError: The view staticApp.views.showBin didn't return an HttpResponse object. It returned None instead.
[2019-03-10 11:03:50,016][Thread-1:354036][task_id:root][views.py:12][INFO][Accessing Page home/ with showHome]
[2019-03-10 11:03:50,383][Thread-3:322764][task_id:django.request][log.py:228][WARNING][Not Found: /wp-content/themes/homesite17/fonts/Stanford.ttf]
[2019-03-10 11:03:50,534][Thread-3:322764][task_id:root][views.py:84][INFO][Accessing /master.css.map with showBin matched nothing.]
[2019-03-10 11:03:50,535][Thread-3:322764][task_id:django.request][log.py:228][ERROR][Internal Server Error: /bin/master.css.map]
Traceback (most recent call last):
  File "D:\Project\Website\venv\lib\site-packages\django\core\handlers\exception.py", line 34, in inner
    response = get_response(request)
  File "D:\Project\Website\venv\lib\site-packages\django\core\handlers\base.py", line 137, in _get_response
    "returned None instead." % (callback.__module__, view_name)
ValueError: The view staticApp.views.showBin didn't return an HttpResponse object. It returned None instead.
[2019-03-10 11:03:50,659][Thread-3:322764][task_id:django.request][log.py:228][WARNING][Not Found: /wp-content/themes/homesite17/fonts/Stanford.woff]
[2019-03-10 11:04:35,987][Thread-6:342176][task_id:root][views.py:84][INFO][Accessing /master.css.map with showBin matched nothing.]
[2019-03-10 11:04:35,988][Thread-6:342176][task_id:django.request][log.py:228][ERROR][Internal Server Error: /bin/master.css.map]
Traceback (most recent call last):
  File "D:\Project\Website\venv\lib\site-packages\django\core\handlers\exception.py", line 34, in inner
    response = get_response(request)
  File "D:\Project\Website\venv\lib\site-packages\django\core\handlers\base.py", line 137, in _get_response
    "returned None instead." % (callback.__module__, view_name)
ValueError: The view staticApp.views.showBin didn't return an HttpResponse object. It returned None instead.
[2019-03-10 11:05:42,853][Thread-1:289876][task_id:root][views.py:12][INFO][Accessing Page home/ with showHome]
[2019-03-10 11:05:43,342][Thread-4:354768][task_id:root][views.py:84][INFO][Accessing /master.css.map with showBin matched nothing.]
[2019-03-10 11:05:43,350][Thread-4:354768][task_id:django.request][log.py:228][ERROR][Internal Server Error: /bin/master.css.map]
Traceback (most recent call last):
  File "D:\Project\Website\venv\lib\site-packages\django\core\handlers\exception.py", line 34, in inner
    response = get_response(request)
  File "D:\Project\Website\venv\lib\site-packages\django\core\handlers\base.py", line 137, in _get_response
    "returned None instead." % (callback.__module__, view_name)
ValueError: The view staticApp.views.showBin didn't return an HttpResponse object. It returned None instead.
[2019-03-10 11:05:43,465][Thread-4:354768][task_id:django.request][log.py:228][WARNING][Not Found: /wp-content/themes/homesite17/fonts/Stanford.ttf]
[2019-03-10 11:05:43,537][Thread-3:353396][task_id:django.request][log.py:228][WARNING][Not Found: /wp-content/themes/homesite17/fonts/Stanford.woff]
[2019-03-10 11:43:44,142][Thread-1:358384][task_id:root][views.py:15][INFO][Accessing Page / with showMainPage]
[2019-03-10 11:43:48,828][Thread-1:358384][task_id:root][views.py:12][INFO][Accessing Page home/ with showHome]
[2019-03-10 11:43:49,083][Thread-6:358012][task_id:django.request][log.py:228][WARNING][Not Found: /wp-content/themes/homesite17/fonts/Stanford.ttf]
[2019-03-10 11:43:49,323][Thread-5:358068][task_id:django.request][log.py:228][WARNING][Not Found: /wp-content/themes/homesite17/fonts/Stanford.woff]
[2019-03-10 12:04:13,057][Thread-1:358284][task_id:root][views.py:12][INFO][Accessing Page home/ with showHome]
[2019-03-10 12:04:13,351][Thread-6:358516][task_id:django.request][log.py:228][WARNING][Not Found: /wp-content/themes/homesite17/fonts/Stanford.ttf]
[2019-03-10 12:04:13,453][Thread-6:358516][task_id:django.request][log.py:228][WARNING][Not Found: /wp-content/themes/homesite17/fonts/Stanford.woff]
[2019-03-10 12:04:33,624][Thread-7:357364][task_id:root][views.py:12][INFO][Accessing Page home/ with showHome]
[2019-03-10 12:04:34,878][Thread-8:354848][task_id:django.request][log.py:228][WARNING][Not Found: /wp-content/themes/homesite17/fonts/Stanford.ttf]
[2019-03-10 12:04:35,157][Thread-11:358156][task_id:django.request][log.py:228][WARNING][Not Found: /wp-content/themes/homesite17/fonts/Stanford.woff]
